2017-02-13 13:38:15,855 t_global_data.py[line:25] INFO -------Global_data init
2017-02-13 13:38:15,855 t_global_data.py[line:27] INFO -------FILE_PATH F:\pythonCode\lxdzx/files/
2017-02-13 13:38:15,857 t_global_data.py[line:28] INFO -------Global_data init over
2017-02-13 13:38:16,242 t_global_data.py[line:25] INFO -------Global_data init
2017-02-13 13:38:16,243 t_global_data.py[line:27] INFO -------FILE_PATH F:\pythonCode\lxdzx/files/
2017-02-13 13:38:16,243 t_global_data.py[line:28] INFO -------Global_data init over
2017-02-13 13:38:26,227 base.py[line:152] WARNING Not Found: /favicon.ico
2017-02-13 13:38:26,799 base.py[line:152] WARNING Not Found: /favicon.ico
2017-02-13 17:15:02,805 t_global_data.py[line:25] INFO -------Global_data init
2017-02-13 17:15:02,826 t_global_data.py[line:27] INFO -------FILE_PATH F:\pythonCode\lxdzx/files/
2017-02-13 17:15:02,828 t_global_data.py[line:28] INFO -------Global_data init over
2017-02-13 17:15:05,380 t_global_data.py[line:25] INFO -------Global_data init
2017-02-13 17:15:05,381 t_global_data.py[line:27] INFO -------FILE_PATH F:\pythonCode\lxdzx/files/
2017-02-13 17:15:05,381 t_global_data.py[line:28] INFO -------Global_data init over
2017-02-13 17:15:19,028 t_global_data.py[line:25] INFO -------Global_data init
2017-02-13 17:15:19,028 t_global_data.py[line:27] INFO -------FILE_PATH F:\pythonCode\lxdzx/files/
2017-02-13 17:15:19,028 t_global_data.py[line:28] INFO -------Global_data init over
2017-02-13 17:22:09,946 t_global_data.py[line:25] INFO -------Global_data init
2017-02-13 17:22:09,947 t_global_data.py[line:27] INFO -------FILE_PATH F:\pythonCode\lxdzx/files/
2017-02-13 17:22:09,947 t_global_data.py[line:28] INFO -------Global_data init over
2017-02-13 17:22:35,709 t_global_data.py[line:25] INFO -------Global_data init
2017-02-13 17:22:35,709 t_global_data.py[line:27] INFO -------FILE_PATH F:\pythonCode\lxdzx/files/
2017-02-13 17:22:35,710 t_global_data.py[line:28] INFO -------Global_data init over
2017-02-13 17:23:04,440 t_global_data.py[line:25] INFO -------Global_data init
2017-02-13 17:23:04,440 t_global_data.py[line:27] INFO -------FILE_PATH F:\pythonCode\lxdzx/files/
2017-02-13 17:23:04,441 t_global_data.py[line:28] INFO -------Global_data init over
2017-02-13 17:23:08,151 t_global_data.py[line:25] INFO -------Global_data init
2017-02-13 17:23:08,151 t_global_data.py[line:27] INFO -------FILE_PATH F:\pythonCode\lxdzx/files/
2017-02-13 17:23:08,151 t_global_data.py[line:28] INFO -------Global_data init over
2017-02-13 17:23:27,522 t_global_data.py[line:25] INFO -------Global_data init
2017-02-13 17:23:27,523 t_global_data.py[line:27] INFO -------FILE_PATH F:\pythonCode\lxdzx/files/
2017-02-13 17:23:27,523 t_global_data.py[line:28] INFO -------Global_data init over
2017-02-13 17:23:32,243 t_global_data.py[line:25] INFO -------Global_data init
2017-02-13 17:23:32,243 t_global_data.py[line:27] INFO -------FILE_PATH F:\pythonCode\lxdzx/files/
2017-02-13 17:23:32,243 t_global_data.py[line:28] INFO -------Global_data init over
2017-02-13 17:25:32,756 t_global_data.py[line:25] INFO -------Global_data init
2017-02-13 17:25:32,756 t_global_data.py[line:27] INFO -------FILE_PATH F:\pythonCode\lxdzx/files/
2017-02-13 17:25:32,756 t_global_data.py[line:28] INFO -------Global_data init over
2017-02-13 17:25:57,290 t_global_data.py[line:25] INFO -------Global_data init
2017-02-13 17:25:57,292 t_global_data.py[line:27] INFO -------FILE_PATH F:\pythonCode\lxdzx/files/
2017-02-13 17:25:57,292 t_global_data.py[line:28] INFO -------Global_data init over
2017-02-13 17:26:23,006 t_global_data.py[line:25] INFO -------Global_data init
2017-02-13 17:26:23,006 t_global_data.py[line:27] INFO -------FILE_PATH F:\pythonCode\lxdzx/files/
2017-02-13 17:26:23,006 t_global_data.py[line:28] INFO -------Global_data init over
2017-02-13 17:26:23,359 t_global_data.py[line:25] INFO -------Global_data init
2017-02-13 17:26:23,361 t_global_data.py[line:27] INFO -------FILE_PATH F:\pythonCode\lxdzx/files/
2017-02-13 17:26:23,361 t_global_data.py[line:28] INFO -------Global_data init over
2017-02-13 17:27:01,358 t_global_data.py[line:25] INFO -------Global_data init
2017-02-13 17:27:01,358 t_global_data.py[line:27] INFO -------FILE_PATH F:\pythonCode\lxdzx/files/
2017-02-13 17:27:01,359 t_global_data.py[line:28] INFO -------Global_data init over
2017-02-13 17:27:32,322 t_global_data.py[line:25] INFO -------Global_data init
2017-02-13 17:27:32,322 t_global_data.py[line:27] INFO -------FILE_PATH F:\pythonCode\lxdzx/files/
2017-02-13 17:27:32,322 t_global_data.py[line:28] INFO -------Global_data init over
2017-02-13 17:28:24,993 t_global_data.py[line:25] INFO -------Global_data init
2017-02-13 17:28:24,994 t_global_data.py[line:27] INFO -------FILE_PATH F:\pythonCode\lxdzx/files/
2017-02-13 17:28:24,994 t_global_data.py[line:28] INFO -------Global_data init over
2017-02-14 10:27:54,799 t_global_data.py[line:25] INFO -------Global_data init
2017-02-14 10:27:54,799 t_global_data.py[line:27] INFO -------FILE_PATH F:\pythonCode\lxdzx/files/
2017-02-14 10:27:54,799 t_global_data.py[line:28] INFO -------Global_data init over
2017-02-14 10:27:55,201 t_global_data.py[line:25] INFO -------Global_data init
2017-02-14 10:27:55,201 t_global_data.py[line:27] INFO -------FILE_PATH F:\pythonCode\lxdzx/files/
2017-02-14 10:27:55,201 t_global_data.py[line:28] INFO -------Global_data init over
2017-02-14 10:28:28,355 t_global_data.py[line:25] INFO -------Global_data init
2017-02-14 10:28:28,355 t_global_data.py[line:27] INFO -------FILE_PATH F:\pythonCode\lxdzx/files/
2017-02-14 10:28:28,355 t_global_data.py[line:28] INFO -------Global_data init over
2017-02-14 10:28:33,128 t_global_data.py[line:25] INFO -------Global_data init
2017-02-14 10:28:33,128 t_global_data.py[line:27] INFO -------FILE_PATH F:\pythonCode\lxdzx/files/
2017-02-14 10:28:33,128 t_global_data.py[line:28] INFO -------Global_data init over
2017-02-14 10:28:51,680 base.py[line:152] WARNING Not Found: /favicon.ico
2017-02-14 10:30:10,232 t_global_data.py[line:25] INFO -------Global_data init
2017-02-14 10:30:10,233 t_global_data.py[line:27] INFO -------FILE_PATH F:\pythonCode\lxdzx/files/
2017-02-14 10:30:10,233 t_global_data.py[line:28] INFO -------Global_data init over
2017-02-14 10:31:26,351 base.py[line:152] WARNING Not Found: /favicon.ico
2017-02-14 11:06:12,456 base.py[line:152] WARNING Not Found: /index.html
2017-02-14 11:30:26,575 base.py[line:152] WARNING Not Found: /index.html
2017-02-14 11:30:27,730 base.py[line:152] WARNING Not Found: /index.html
2017-02-14 11:30:27,987 base.py[line:152] WARNING Not Found: /index.html
2017-02-14 11:30:28,224 base.py[line:152] WARNING Not Found: /index.html
2017-02-14 11:30:28,433 base.py[line:152] WARNING Not Found: /index.html
2017-02-15 10:20:12,052 base.py[line:152] WARNING Not Found: /reg/1
2017-02-15 11:02:12,546 t_global_data.py[line:25] INFO -------Global_data init
2017-02-15 11:02:12,546 t_global_data.py[line:27] INFO -------FILE_PATH F:\pythonCode\lxdzx/files/
2017-02-15 11:02:12,546 t_global_data.py[line:28] INFO -------Global_data init over
2017-02-15 11:02:50,486 t_global_data.py[line:25] INFO -------Global_data init
2017-02-15 11:02:50,486 t_global_data.py[line:27] INFO -------FILE_PATH F:\pythonCode\lxdzx/files/
2017-02-15 11:02:50,486 t_global_data.py[line:28] INFO -------Global_data init over
2017-02-15 11:03:03,109 t_global_data.py[line:25] INFO -------Global_data init
2017-02-15 11:03:03,111 t_global_data.py[line:27] INFO -------FILE_PATH F:\pythonCode\lxdzx/files/
2017-02-15 11:03:03,111 t_global_data.py[line:28] INFO -------Global_data init over
2017-02-15 11:06:42,387 t_global_data.py[line:25] INFO -------Global_data init
2017-02-15 11:06:42,387 t_global_data.py[line:27] INFO -------FILE_PATH F:\pythonCode\lxdzx/files/
2017-02-15 11:06:42,388 t_global_data.py[line:28] INFO -------Global_data init over
2017-02-15 11:06:47,903 t_global_data.py[line:25] INFO -------Global_data init
2017-02-15 11:06:47,903 t_global_data.py[line:27] INFO -------FILE_PATH F:\pythonCode\lxdzx/files/
2017-02-15 11:06:47,904 t_global_data.py[line:28] INFO -------Global_data init over
2017-02-15 11:06:50,328 t_global_data.py[line:25] INFO -------Global_data init
2017-02-15 11:06:50,328 t_global_data.py[line:27] INFO -------FILE_PATH F:\pythonCode\lxdzx/files/
2017-02-15 11:06:50,329 t_global_data.py[line:28] INFO -------Global_data init over
2017-02-15 11:07:36,561 t_global_data.py[line:25] INFO -------Global_data init
2017-02-15 11:07:36,561 t_global_data.py[line:27] INFO -------FILE_PATH F:\pythonCode\lxdzx/files/
2017-02-15 11:07:36,562 t_global_data.py[line:28] INFO -------Global_data init over
2017-02-15 11:07:45,104 t_global_data.py[line:25] INFO -------Global_data init
2017-02-15 11:07:45,105 t_global_data.py[line:27] INFO -------FILE_PATH F:\pythonCode\lxdzx/files/
2017-02-15 11:07:45,105 t_global_data.py[line:28] INFO -------Global_data init over
2017-02-15 11:07:48,775 t_global_data.py[line:25] INFO -------Global_data init
2017-02-15 11:07:48,776 t_global_data.py[line:27] INFO -------FILE_PATH F:\pythonCode\lxdzx/files/
2017-02-15 11:07:48,776 t_global_data.py[line:28] INFO -------Global_data init over
2017-02-15 11:07:51,765 t_global_data.py[line:25] INFO -------Global_data init
2017-02-15 11:07:51,766 t_global_data.py[line:27] INFO -------FILE_PATH F:\pythonCode\lxdzx/files/
2017-02-15 11:07:51,766 t_global_data.py[line:28] INFO -------Global_data init over
2017-02-15 11:08:12,526 t_global_data.py[line:25] INFO -------Global_data init
2017-02-15 11:08:12,526 t_global_data.py[line:27] INFO -------FILE_PATH F:\pythonCode\lxdzx/files/
2017-02-15 11:08:12,528 t_global_data.py[line:28] INFO -------Global_data init over
2017-02-15 11:08:24,115 t_global_data.py[line:25] INFO -------Global_data init
2017-02-15 11:08:24,115 t_global_data.py[line:27] INFO -------FILE_PATH F:\pythonCode\lxdzx/files/
2017-02-15 11:08:24,115 t_global_data.py[line:28] INFO -------Global_data init over
2017-02-15 11:08:52,062 t_global_data.py[line:25] INFO -------Global_data init
2017-02-15 11:08:52,062 t_global_data.py[line:27] INFO -------FILE_PATH F:\pythonCode\lxdzx/files/
2017-02-15 11:08:52,062 t_global_data.py[line:28] INFO -------Global_data init over
2017-02-15 11:08:58,352 t_global_data.py[line:25] INFO -------Global_data init
2017-02-15 11:08:58,354 t_global_data.py[line:27] INFO -------FILE_PATH F:\pythonCode\lxdzx/files/
2017-02-15 11:08:58,354 t_global_data.py[line:28] INFO -------Global_data init over
2017-02-15 11:09:09,096 t_global_data.py[line:25] INFO -------Global_data init
2017-02-15 11:09:09,096 t_global_data.py[line:27] INFO -------FILE_PATH F:\pythonCode\lxdzx/files/
2017-02-15 11:09:09,096 t_global_data.py[line:28] INFO -------Global_data init over
2017-02-15 11:09:34,651 t_global_data.py[line:25] INFO -------Global_data init
2017-02-15 11:09:34,653 t_global_data.py[line:27] INFO -------FILE_PATH F:\pythonCode\lxdzx/files/
2017-02-15 11:09:34,653 t_global_data.py[line:28] INFO -------Global_data init over
2017-02-15 11:09:35,007 t_global_data.py[line:25] INFO -------Global_data init
2017-02-15 11:09:35,007 t_global_data.py[line:27] INFO -------FILE_PATH F:\pythonCode\lxdzx/files/
2017-02-15 11:09:35,007 t_global_data.py[line:28] INFO -------Global_data init over
2017-02-15 13:23:01,539 t_global_data.py[line:25] INFO -------Global_data init
2017-02-15 13:23:01,539 t_global_data.py[line:27] INFO -------FILE_PATH F:\pythonCode\lxdzx/files/
2017-02-15 13:23:01,539 t_global_data.py[line:28] INFO -------Global_data init over
2017-02-15 13:23:14,757 t_global_data.py[line:25] INFO -------Global_data init
2017-02-15 13:23:14,757 t_global_data.py[line:27] INFO -------FILE_PATH F:\pythonCode\lxdzx/files/
2017-02-15 13:23:14,759 t_global_data.py[line:28] INFO -------Global_data init over
2017-02-15 13:23:16,318 t_global_data.py[line:25] INFO -------Global_data init
2017-02-15 13:23:16,319 t_global_data.py[line:27] INFO -------FILE_PATH F:\pythonCode\lxdzx/files/
2017-02-15 13:23:16,319 t_global_data.py[line:28] INFO -------Global_data init over
2017-02-15 13:41:58,973 t_global_data.py[line:25] INFO -------Global_data init
2017-02-15 13:41:58,973 t_global_data.py[line:27] INFO -------FILE_PATH F:\pythonCode\lxdzx/files/
2017-02-15 13:41:58,973 t_global_data.py[line:28] INFO -------Global_data init over
2017-02-15 13:42:05,783 t_global_data.py[line:25] INFO -------Global_data init
2017-02-15 13:42:05,783 t_global_data.py[line:27] INFO -------FILE_PATH F:\pythonCode\lxdzx/files/
2017-02-15 13:42:05,783 t_global_data.py[line:28] INFO -------Global_data init over
2017-02-15 13:42:26,033 t_global_data.py[line:25] INFO -------Global_data init
2017-02-15 13:42:26,033 t_global_data.py[line:27] INFO -------FILE_PATH F:\pythonCode\lxdzx/files/
2017-02-15 13:42:26,033 t_global_data.py[line:28] INFO -------Global_data init over
2017-02-15 13:42:29,716 t_global_data.py[line:25] INFO -------Global_data init
2017-02-15 13:42:29,716 t_global_data.py[line:27] INFO -------FILE_PATH F:\pythonCode\lxdzx/files/
2017-02-15 13:42:29,717 t_global_data.py[line:28] INFO -------Global_data init over
2017-02-15 13:42:45,861 t_global_data.py[line:25] INFO -------Global_data init
2017-02-15 13:42:45,862 t_global_data.py[line:27] INFO -------FILE_PATH F:\pythonCode\lxdzx/files/
2017-02-15 13:42:45,862 t_global_data.py[line:28] INFO -------Global_data init over
2017-02-15 13:42:55,986 t_global_data.py[line:25] INFO -------Global_data init
2017-02-15 13:42:56,000 t_global_data.py[line:27] INFO -------FILE_PATH F:\pythonCode\lxdzx/files/
2017-02-15 13:42:56,002 t_global_data.py[line:28] INFO -------Global_data init over
2017-02-15 13:45:11,611 t_global_data.py[line:25] INFO -------Global_data init
2017-02-15 13:45:11,611 t_global_data.py[line:27] INFO -------FILE_PATH F:\pythonCode\lxdzx/files/
2017-02-15 13:45:11,611 t_global_data.py[line:28] INFO -------Global_data init over
2017-02-15 13:46:33,512 t_global_data.py[line:25] INFO -------Global_data init
2017-02-15 13:46:33,512 t_global_data.py[line:27] INFO -------FILE_PATH F:\pythonCode\lxdzx/files/
2017-02-15 13:46:33,512 t_global_data.py[line:28] INFO -------Global_data init over
2017-02-15 13:46:53,789 t_global_data.py[line:25] INFO -------Global_data init
2017-02-15 13:46:53,789 t_global_data.py[line:27] INFO -------FILE_PATH F:\pythonCode\lxdzx/files/
2017-02-15 13:46:53,789 t_global_data.py[line:28] INFO -------Global_data init over
2017-02-15 13:47:43,131 t_global_data.py[line:25] INFO -------Global_data init
2017-02-15 13:47:43,132 t_global_data.py[line:27] INFO -------FILE_PATH F:\pythonCode\lxdzx/files/
2017-02-15 13:47:43,132 t_global_data.py[line:28] INFO -------Global_data init over
2017-02-15 13:50:43,507 t_global_data.py[line:25] INFO -------Global_data init
2017-02-15 13:50:43,509 t_global_data.py[line:27] INFO -------FILE_PATH F:\pythonCode\lxdzx/files/
2017-02-15 13:50:43,509 t_global_data.py[line:28] INFO -------Global_data init over
2017-02-15 13:50:47,993 t_global_data.py[line:25] INFO -------Global_data init
2017-02-15 13:50:47,993 t_global_data.py[line:27] INFO -------FILE_PATH F:\pythonCode\lxdzx/files/
2017-02-15 13:50:47,993 t_global_data.py[line:28] INFO -------Global_data init over
2017-02-15 13:58:45,892 t_global_data.py[line:25] INFO -------Global_data init
2017-02-15 13:58:45,892 t_global_data.py[line:27] INFO -------FILE_PATH F:\pythonCode\lxdzx/files/
2017-02-15 13:58:45,892 t_global_data.py[line:28] INFO -------Global_data init over
2017-02-15 13:59:02,601 t_global_data.py[line:25] INFO -------Global_data init
2017-02-15 13:59:02,602 t_global_data.py[line:27] INFO -------FILE_PATH F:\pythonCode\lxdzx/files/
2017-02-15 13:59:02,602 t_global_data.py[line:28] INFO -------Global_data init over
2017-02-15 14:00:02,540 t_global_data.py[line:25] INFO -------Global_data init
2017-02-15 14:00:02,540 t_global_data.py[line:27] INFO -------FILE_PATH F:\pythonCode\lxdzx/files/
2017-02-15 14:00:02,540 t_global_data.py[line:28] INFO -------Global_data init over
2017-02-15 14:00:12,119 t_global_data.py[line:25] INFO -------Global_data init
2017-02-15 14:00:12,121 t_global_data.py[line:27] INFO -------FILE_PATH F:\pythonCode\lxdzx/files/
2017-02-15 14:00:12,121 t_global_data.py[line:28] INFO -------Global_data init over
2017-02-15 14:00:18,625 t_global_data.py[line:25] INFO -------Global_data init
2017-02-15 14:00:18,625 t_global_data.py[line:27] INFO -------FILE_PATH F:\pythonCode\lxdzx/files/
2017-02-15 14:00:18,625 t_global_data.py[line:28] INFO -------Global_data init over
2017-02-15 14:00:24,128 t_global_data.py[line:25] INFO -------Global_data init
2017-02-15 14:00:24,128 t_global_data.py[line:27] INFO -------FILE_PATH F:\pythonCode\lxdzx/files/
2017-02-15 14:00:24,128 t_global_data.py[line:28] INFO -------Global_data init over
2017-02-15 14:00:30,640 t_global_data.py[line:25] INFO -------Global_data init
2017-02-15 14:00:30,641 t_global_data.py[line:27] INFO -------FILE_PATH F:\pythonCode\lxdzx/files/
2017-02-15 14:00:30,641 t_global_data.py[line:28] INFO -------Global_data init over
2017-02-15 14:00:55,460 t_global_data.py[line:25] INFO -------Global_data init
2017-02-15 14:00:55,460 t_global_data.py[line:27] INFO -------FILE_PATH F:\pythonCode\lxdzx/files/
2017-02-15 14:00:55,460 t_global_data.py[line:28] INFO -------Global_data init over
2017-02-15 14:00:58,053 t_global_data.py[line:25] INFO -------Global_data init
2017-02-15 14:00:58,055 t_global_data.py[line:27] INFO -------FILE_PATH F:\pythonCode\lxdzx/files/
2017-02-15 14:00:58,055 t_global_data.py[line:28] INFO -------Global_data init over
2017-02-15 14:01:15,772 t_global_data.py[line:25] INFO -------Global_data init
2017-02-15 14:01:15,772 t_global_data.py[line:27] INFO -------FILE_PATH F:\pythonCode\lxdzx/files/
2017-02-15 14:01:15,773 t_global_data.py[line:28] INFO -------Global_data init over
2017-02-15 14:01:48,779 t_global_data.py[line:25] INFO -------Global_data init
2017-02-15 14:01:48,779 t_global_data.py[line:27] INFO -------FILE_PATH F:\pythonCode\lxdzx/files/
2017-02-15 14:01:48,779 t_global_data.py[line:28] INFO -------Global_data init over
2017-02-15 14:01:51,209 t_global_data.py[line:25] INFO -------Global_data init
2017-02-15 14:01:51,209 t_global_data.py[line:27] INFO -------FILE_PATH F:\pythonCode\lxdzx/files/
2017-02-15 14:01:51,210 t_global_data.py[line:28] INFO -------Global_data init over
2017-02-15 14:02:02,825 t_global_data.py[line:25] INFO -------Global_data init
2017-02-15 14:02:02,825 t_global_data.py[line:27] INFO -------FILE_PATH F:\pythonCode\lxdzx/files/
2017-02-15 14:02:02,825 t_global_data.py[line:28] INFO -------Global_data init over
2017-02-15 14:02:14,476 t_global_data.py[line:25] INFO -------Global_data init
2017-02-15 14:02:14,477 t_global_data.py[line:27] INFO -------FILE_PATH F:\pythonCode\lxdzx/files/
2017-02-15 14:02:14,477 t_global_data.py[line:28] INFO -------Global_data init over
2017-02-15 14:02:21,043 t_global_data.py[line:25] INFO -------Global_data init
2017-02-15 14:02:21,043 t_global_data.py[line:27] INFO -------FILE_PATH F:\pythonCode\lxdzx/files/
2017-02-15 14:02:21,043 t_global_data.py[line:28] INFO -------Global_data init over
2017-02-15 14:02:26,545 t_global_data.py[line:25] INFO -------Global_data init
2017-02-15 14:02:26,545 t_global_data.py[line:27] INFO -------FILE_PATH F:\pythonCode\lxdzx/files/
2017-02-15 14:02:26,545 t_global_data.py[line:28] INFO -------Global_data init over
2017-02-15 14:02:29,997 t_global_data.py[line:25] INFO -------Global_data init
2017-02-15 14:02:29,997 t_global_data.py[line:27] INFO -------FILE_PATH F:\pythonCode\lxdzx/files/
2017-02-15 14:02:29,999 t_global_data.py[line:28] INFO -------Global_data init over
2017-02-15 14:02:34,730 t_global_data.py[line:25] INFO -------Global_data init
2017-02-15 14:02:34,730 t_global_data.py[line:27] INFO -------FILE_PATH F:\pythonCode\lxdzx/files/
2017-02-15 14:02:34,732 t_global_data.py[line:28] INFO -------Global_data init over
2017-02-15 14:02:40,463 t_global_data.py[line:25] INFO -------Global_data init
2017-02-15 14:02:40,463 t_global_data.py[line:27] INFO -------FILE_PATH F:\pythonCode\lxdzx/files/
2017-02-15 14:02:40,464 t_global_data.py[line:28] INFO -------Global_data init over
2017-02-15 14:02:43,055 t_global_data.py[line:25] INFO -------Global_data init
2017-02-15 14:02:43,055 t_global_data.py[line:27] INFO -------FILE_PATH F:\pythonCode\lxdzx/files/
2017-02-15 14:02:43,055 t_global_data.py[line:28] INFO -------Global_data init over
2017-02-15 14:06:21,845 t_global_data.py[line:25] INFO -------Global_data init
2017-02-15 14:06:21,845 t_global_data.py[line:27] INFO -------FILE_PATH F:\pythonCode\lxdzx/files/
2017-02-15 14:06:21,845 t_global_data.py[line:28] INFO -------Global_data init over
2017-02-15 14:06:35,900 t_global_data.py[line:25] INFO -------Global_data init
2017-02-15 14:06:35,901 t_global_data.py[line:27] INFO -------FILE_PATH F:\pythonCode\lxdzx/files/
2017-02-15 14:06:35,901 t_global_data.py[line:28] INFO -------Global_data init over
2017-02-15 14:09:52,086 t_global_data.py[line:25] INFO -------Global_data init
2017-02-15 14:09:52,088 t_global_data.py[line:27] INFO -------FILE_PATH F:\pythonCode\lxdzx/files/
2017-02-15 14:09:52,088 t_global_data.py[line:28] INFO -------Global_data init over
2017-02-15 14:10:00,684 t_global_data.py[line:25] INFO -------Global_data init
2017-02-15 14:10:00,684 t_global_data.py[line:27] INFO -------FILE_PATH F:\pythonCode\lxdzx/files/
2017-02-15 14:10:00,684 t_global_data.py[line:28] INFO -------Global_data init over
2017-02-15 14:10:07,197 t_global_data.py[line:25] INFO -------Global_data init
2017-02-15 14:10:07,197 t_global_data.py[line:27] INFO -------FILE_PATH F:\pythonCode\lxdzx/files/
2017-02-15 14:10:07,197 t_global_data.py[line:28] INFO -------Global_data init over
2017-02-15 14:10:39,190 t_global_data.py[line:25] INFO -------Global_data init
2017-02-15 14:10:39,190 t_global_data.py[line:27] INFO -------FILE_PATH F:\pythonCode\lxdzx/files/
2017-02-15 14:10:39,190 t_global_data.py[line:28] INFO -------Global_data init over
2017-02-15 14:10:41,788 t_global_data.py[line:25] INFO -------Global_data init
2017-02-15 14:10:41,789 t_global_data.py[line:27] INFO -------FILE_PATH F:\pythonCode\lxdzx/files/
2017-02-15 14:10:41,789 t_global_data.py[line:28] INFO -------Global_data init over
2017-02-15 14:11:14,250 base.py[line:152] WARNING Not Found: /adin
2017-02-15 14:12:10,046 t_global_data.py[line:25] INFO -------Global_data init
2017-02-15 14:12:10,046 t_global_data.py[line:27] INFO -------FILE_PATH F:\pythonCode\lxdzx/files/
2017-02-15 14:12:10,048 t_global_data.py[line:28] INFO -------Global_data init over
2017-02-15 14:12:11,618 t_global_data.py[line:25] INFO -------Global_data init
2017-02-15 14:12:11,618 t_global_data.py[line:27] INFO -------FILE_PATH F:\pythonCode\lxdzx/files/
2017-02-15 14:12:11,618 t_global_data.py[line:28] INFO -------Global_data init over
2017-02-15 14:12:15,273 t_global_data.py[line:25] INFO -------Global_data init
2017-02-15 14:12:15,273 t_global_data.py[line:27] INFO -------FILE_PATH F:\pythonCode\lxdzx/files/
2017-02-15 14:12:15,273 t_global_data.py[line:28] INFO -------Global_data init over
2017-02-15 14:12:25,164 t_global_data.py[line:25] INFO -------Global_data init
2017-02-15 14:12:25,164 t_global_data.py[line:27] INFO -------FILE_PATH F:\pythonCode\lxdzx/files/
2017-02-15 14:12:25,164 t_global_data.py[line:28] INFO -------Global_data init over
2017-02-15 14:13:10,927 exception.py[line:124] ERROR Internal Server Error: /admin/videos_manager/tags/1/change/
Traceback (most recent call last):
  File "F:\Python27\lib\site-packages\django\core\handlers\exception.py", line 39, in inner
    response = get_response(request)
  File "F:\Python27\lib\site-packages\django\core\handlers\base.py", line 187, in _get_response
    response = self.process_exception_by_middleware(e, request)
  File "F:\Python27\lib\site-packages\django\core\handlers\base.py", line 185, in _get_response
    response = wrapped_callback(request, *callback_args, **callback_kwargs)
  File "F:\Python27\lib\site-packages\django\contrib\admin\options.py", line 544, in wrapper
    return self.admin_site.admin_view(view)(*args, **kwargs)
  File "F:\Python27\lib\site-packages\django\utils\decorators.py", line 149, in _wrapped_view
    response = view_func(request, *args, **kwargs)
  File "F:\Python27\lib\site-packages\django\views\decorators\cache.py", line 57, in _wrapped_view_func
    response = view_func(request, *args, **kwargs)
  File "F:\Python27\lib\site-packages\django\contrib\admin\sites.py", line 211, in inner
    return view(request, *args, **kwargs)
  File "F:\Python27\lib\site-packages\django\contrib\admin\options.py", line 1512, in change_view
    return self.changeform_view(request, object_id, form_url, extra_context)
  File "F:\Python27\lib\site-packages\django\utils\decorators.py", line 67, in _wrapper
    return bound_func(*args, **kwargs)
  File "F:\Python27\lib\site-packages\django\utils\decorators.py", line 149, in _wrapped_view
    response = view_func(request, *args, **kwargs)
  File "F:\Python27\lib\site-packages\django\utils\decorators.py", line 63, in bound_func
    return func.__get__(self, type(self))(*args2, **kwargs2)
  File "F:\Python27\lib\site-packages\django\utils\decorators.py", line 185, in inner
    return func(*args, **kwargs)
  File "F:\Python27\lib\site-packages\django\contrib\admin\options.py", line 1429, in changeform_view
    obj = self.get_object(request, unquote(object_id), to_field)
  File "F:\Python27\lib\site-packages\django\contrib\admin\options.py", line 667, in get_object
    return queryset.get(**{field.name: object_id})
  File "F:\Python27\lib\site-packages\django\db\models\query.py", line 379, in get
    num = len(clone)
  File "F:\Python27\lib\site-packages\django\db\models\query.py", line 238, in __len__
    self._fetch_all()
  File "F:\Python27\lib\site-packages\django\db\models\query.py", line 1087, in _fetch_all
    self._result_cache = list(self.iterator())
  File "F:\Python27\lib\site-packages\django\db\models\query.py", line 54, in __iter__
    results = compiler.execute_sql()
  File "F:\Python27\lib\site-packages\django\db\models\sql\compiler.py", line 835, in execute_sql
    cursor.execute(sql, params)
  File "F:\Python27\lib\site-packages\django\db\backends\utils.py", line 79, in execute
    return super(CursorDebugWrapper, self).execute(sql, params)
  File "F:\Python27\lib\site-packages\django\db\backends\utils.py", line 64, in execute
    return self.cursor.execute(sql, params)
  File "F:\Python27\lib\site-packages\django\db\utils.py", line 94, in __exit__
    six.reraise(dj_exc_type, dj_exc_value, traceback)
  File "F:\Python27\lib\site-packages\django\db\backends\utils.py", line 64, in execute
    return self.cursor.execute(sql, params)
  File "F:\Python27\lib\site-packages\django\db\backends\sqlite3\base.py", line 337, in execute
    return Database.Cursor.execute(self, query, params)
OperationalError: no such column: videos_manager_tags.desc
2017-02-15 14:13:20,269 exception.py[line:124] ERROR Internal Server Error: /admin/videos_manager/tags/
Traceback (most recent call last):
  File "F:\Python27\lib\site-packages\django\core\handlers\exception.py", line 39, in inner
    response = get_response(request)
  File "F:\Python27\lib\site-packages\django\core\handlers\base.py", line 187, in _get_response
    response = self.process_exception_by_middleware(e, request)
  File "F:\Python27\lib\site-packages\django\core\handlers\base.py", line 185, in _get_response
    response = wrapped_callback(request, *callback_args, **callback_kwargs)
  File "F:\Python27\lib\site-packages\django\contrib\admin\options.py", line 544, in wrapper
    return self.admin_site.admin_view(view)(*args, **kwargs)
  File "F:\Python27\lib\site-packages\django\utils\decorators.py", line 149, in _wrapped_view
    response = view_func(request, *args, **kwargs)
  File "F:\Python27\lib\site-packages\django\views\decorators\cache.py", line 57, in _wrapped_view_func
    response = view_func(request, *args, **kwargs)
  File "F:\Python27\lib\site-packages\django\contrib\admin\sites.py", line 211, in inner
    return view(request, *args, **kwargs)
  File "F:\Python27\lib\site-packages\django\utils\decorators.py", line 67, in _wrapper
    return bound_func(*args, **kwargs)
  File "F:\Python27\lib\site-packages\django\utils\decorators.py", line 149, in _wrapped_view
    response = view_func(request, *args, **kwargs)
  File "F:\Python27\lib\site-packages\django\utils\decorators.py", line 63, in bound_func
    return func.__get__(self, type(self))(*args2, **kwargs2)
  File "F:\Python27\lib\site-packages\django\contrib\admin\options.py", line 1657, in changelist_view
    selection_note=_('0 of %(cnt)s selected') % {'cnt': len(cl.result_list)},
  File "F:\Python27\lib\site-packages\django\db\models\query.py", line 238, in __len__
    self._fetch_all()
  File "F:\Python27\lib\site-packages\django\db\models\query.py", line 1087, in _fetch_all
    self._result_cache = list(self.iterator())
  File "F:\Python27\lib\site-packages\django\db\models\query.py", line 54, in __iter__
    results = compiler.execute_sql()
  File "F:\Python27\lib\site-packages\django\db\models\sql\compiler.py", line 835, in execute_sql
    cursor.execute(sql, params)
  File "F:\Python27\lib\site-packages\django\db\backends\utils.py", line 79, in execute
    return super(CursorDebugWrapper, self).execute(sql, params)
  File "F:\Python27\lib\site-packages\django\db\backends\utils.py", line 64, in execute
    return self.cursor.execute(sql, params)
  File "F:\Python27\lib\site-packages\django\db\utils.py", line 94, in __exit__
    six.reraise(dj_exc_type, dj_exc_value, traceback)
  File "F:\Python27\lib\site-packages\django\db\backends\utils.py", line 64, in execute
    return self.cursor.execute(sql, params)
  File "F:\Python27\lib\site-packages\django\db\backends\sqlite3\base.py", line 337, in execute
    return Database.Cursor.execute(self, query, params)
OperationalError: no such column: videos_manager_tags.desc
2017-02-15 14:15:28,778 t_global_data.py[line:25] INFO -------Global_data init
2017-02-15 14:15:28,779 t_global_data.py[line:27] INFO -------FILE_PATH F:\pythonCode\lxdzx/files/
2017-02-15 14:15:28,779 t_global_data.py[line:28] INFO -------Global_data init over
2017-02-15 14:15:38,720 t_global_data.py[line:25] INFO -------Global_data init
2017-02-15 14:15:38,720 t_global_data.py[line:27] INFO -------FILE_PATH F:\pythonCode\lxdzx/files/
2017-02-15 14:15:38,720 t_global_data.py[line:28] INFO -------Global_data init over
2017-02-15 14:16:44,855 t_global_data.py[line:25] INFO -------Global_data init
2017-02-15 14:16:44,855 t_global_data.py[line:27] INFO -------FILE_PATH F:\pythonCode\lxdzx/files/
2017-02-15 14:16:44,855 t_global_data.py[line:28] INFO -------Global_data init over
2017-02-15 14:16:51,612 t_global_data.py[line:25] INFO -------Global_data init
2017-02-15 14:16:51,612 t_global_data.py[line:27] INFO -------FILE_PATH F:\pythonCode\lxdzx/files/
2017-02-15 14:16:51,612 t_global_data.py[line:28] INFO -------Global_data init over
2017-02-15 14:16:59,464 t_global_data.py[line:25] INFO -------Global_data init
2017-02-15 14:16:59,466 t_global_data.py[line:27] INFO -------FILE_PATH F:\pythonCode\lxdzx/files/
2017-02-15 14:16:59,466 t_global_data.py[line:28] INFO -------Global_data init over
2017-02-15 14:17:38,546 t_global_data.py[line:25] INFO -------Global_data init
2017-02-15 14:17:38,546 t_global_data.py[line:27] INFO -------FILE_PATH F:\pythonCode\lxdzx/files/
2017-02-15 14:17:38,546 t_global_data.py[line:28] INFO -------Global_data init over
2017-02-15 14:17:49,601 t_global_data.py[line:25] INFO -------Global_data init
2017-02-15 14:17:49,601 t_global_data.py[line:27] INFO -------FILE_PATH F:\pythonCode\lxdzx/files/
2017-02-15 14:17:49,605 t_global_data.py[line:28] INFO -------Global_data init over
2017-02-15 14:18:30,697 t_global_data.py[line:25] INFO -------Global_data init
2017-02-15 14:18:30,697 t_global_data.py[line:27] INFO -------FILE_PATH F:\pythonCode\lxdzx/files/
2017-02-15 14:18:30,697 t_global_data.py[line:28] INFO -------Global_data init over
2017-02-15 14:21:09,367 t_global_data.py[line:25] INFO -------Global_data init
2017-02-15 14:21:09,367 t_global_data.py[line:27] INFO -------FILE_PATH F:\pythonCode\lxdzx/files/
2017-02-15 14:21:09,367 t_global_data.py[line:28] INFO -------Global_data init over
2017-02-15 14:21:55,575 t_global_data.py[line:25] INFO -------Global_data init
2017-02-15 14:21:55,575 t_global_data.py[line:27] INFO -------FILE_PATH F:\pythonCode\lxdzx/files/
2017-02-15 14:21:55,575 t_global_data.py[line:28] INFO -------Global_data init over
2017-02-15 14:22:13,309 t_global_data.py[line:25] INFO -------Global_data init
2017-02-15 14:22:13,309 t_global_data.py[line:27] INFO -------FILE_PATH F:\pythonCode\lxdzx/files/
2017-02-15 14:22:13,309 t_global_data.py[line:28] INFO -------Global_data init over
2017-02-15 14:25:56,348 t_global_data.py[line:25] INFO -------Global_data init
2017-02-15 14:25:56,348 t_global_data.py[line:27] INFO -------FILE_PATH F:\pythonCode\lxdzx/files/
2017-02-15 14:25:56,348 t_global_data.py[line:28] INFO -------Global_data init over
2017-02-15 14:26:05,197 t_global_data.py[line:25] INFO -------Global_data init
2017-02-15 14:26:05,197 t_global_data.py[line:27] INFO -------FILE_PATH F:\pythonCode\lxdzx/files/
2017-02-15 14:26:05,197 t_global_data.py[line:28] INFO -------Global_data init over
2017-02-15 14:26:08,842 t_global_data.py[line:25] INFO -------Global_data init
2017-02-15 14:26:08,842 t_global_data.py[line:27] INFO -------FILE_PATH F:\pythonCode\lxdzx/files/
2017-02-15 14:26:08,842 t_global_data.py[line:28] INFO -------Global_data init over
2017-02-15 14:59:44,407 base.py[line:152] WARNING Not Found: /files/recv/002.jpg
2017-02-15 15:00:26,559 t_global_data.py[line:26] INFO -------Global_data init
2017-02-15 15:00:26,559 t_global_data.py[line:28] INFO -------FILE_PATH F:\pythonCode\lxdzx/static/
2017-02-15 15:00:26,561 t_global_data.py[line:29] INFO -------Global_data init over
2017-02-15 15:00:30,204 t_global_data.py[line:26] INFO -------Global_data init
2017-02-15 15:00:30,204 t_global_data.py[line:28] INFO -------FILE_PATH F:\pythonCode\lxdzx/static/files/
2017-02-15 15:00:30,204 t_global_data.py[line:29] INFO -------Global_data init over
2017-02-15 15:00:39,124 t_global_data.py[line:26] INFO -------Global_data init
2017-02-15 15:00:39,124 t_global_data.py[line:28] INFO -------FILE_PATH F:\pythonCode\lxdzx/files/
2017-02-15 15:00:39,125 t_global_data.py[line:29] INFO -------Global_data init over
2017-02-15 15:00:40,709 t_global_data.py[line:26] INFO -------Global_data init
2017-02-15 15:00:40,710 t_global_data.py[line:28] INFO -------FILE_PATH F:\pythonCode\lxdzx/files/
2017-02-15 15:00:40,710 t_global_data.py[line:29] INFO -------Global_data init over
2017-02-15 15:00:49,877 base.py[line:152] WARNING Not Found: /files/recv/002.jpg
2017-02-15 15:00:50,628 base.py[line:152] WARNING Not Found: /files/recv/002.jpg
2017-02-15 15:00:50,834 base.py[line:152] WARNING Not Found: /files/recv/002.jpg
2017-02-15 15:00:50,996 base.py[line:152] WARNING Not Found: /files/recv/002.jpg
2017-02-15 15:04:41,450 t_global_data.py[line:26] INFO -------Global_data init
2017-02-15 15:04:41,450 t_global_data.py[line:28] INFO -------FILE_PATH F:\pythonCode\lxdzx/files/
2017-02-15 15:04:41,450 t_global_data.py[line:29] INFO -------Global_data init over
2017-02-15 15:04:52,415 t_global_data.py[line:26] INFO -------Global_data init
2017-02-15 15:04:52,417 t_global_data.py[line:28] INFO -------FILE_PATH F:\pythonCode\lxdzx/files/
2017-02-15 15:04:52,417 t_global_data.py[line:29] INFO -------Global_data init over
2017-02-15 15:05:01,260 t_global_data.py[line:26] INFO -------Global_data init
2017-02-15 15:05:01,260 t_global_data.py[line:28] INFO -------FILE_PATH F:\pythonCode\lxdzx/files/
2017-02-15 15:05:01,260 t_global_data.py[line:29] INFO -------Global_data init over
2017-02-15 15:05:44,486 t_global_data.py[line:26] INFO -------Global_data init
2017-02-15 15:05:44,486 t_global_data.py[line:28] INFO -------FILE_PATH F:\pythonCode\lxdzx/files/
2017-02-15 15:05:44,486 t_global_data.py[line:29] INFO -------Global_data init over
2017-02-15 15:06:13,117 t_global_data.py[line:26] INFO -------Global_data init
2017-02-15 15:06:13,117 t_global_data.py[line:28] INFO -------FILE_PATH F:\pythonCode\lxdzx/files/
2017-02-15 15:06:13,117 t_global_data.py[line:29] INFO -------Global_data init over
2017-02-15 15:06:42,045 t_global_data.py[line:26] INFO -------Global_data init
2017-02-15 15:06:42,045 t_global_data.py[line:28] INFO -------FILE_PATH F:\pythonCode\lxdzx/files/
2017-02-15 15:06:42,045 t_global_data.py[line:29] INFO -------Global_data init over
2017-02-15 15:06:52,625 t_global_data.py[line:26] INFO -------Global_data init
2017-02-15 15:06:52,625 t_global_data.py[line:28] INFO -------FILE_PATH F:\pythonCode\lxdzx/files/
2017-02-15 15:06:52,625 t_global_data.py[line:29] INFO -------Global_data init over
2017-02-15 15:06:59,400 t_global_data.py[line:26] INFO -------Global_data init
2017-02-15 15:06:59,400 t_global_data.py[line:28] INFO -------FILE_PATH F:\pythonCode\lxdzx/files/
2017-02-15 15:06:59,400 t_global_data.py[line:29] INFO -------Global_data init over
2017-02-15 15:07:10,335 t_global_data.py[line:26] INFO -------Global_data init
2017-02-15 15:07:10,335 t_global_data.py[line:28] INFO -------FILE_PATH F:\pythonCode\lxdzx/files/
2017-02-15 15:07:10,335 t_global_data.py[line:29] INFO -------Global_data init over
2017-02-15 15:08:06,019 t_global_data.py[line:26] INFO -------Global_data init
2017-02-15 15:08:06,020 t_global_data.py[line:28] INFO -------FILE_PATH F:\pythonCode\lxdzx/files/
2017-02-15 15:08:06,020 t_global_data.py[line:29] INFO -------Global_data init over
2017-02-15 15:11:11,009 t_global_data.py[line:26] INFO -------Global_data init
2017-02-15 15:11:11,010 t_global_data.py[line:28] INFO -------FILE_PATH F:\pythonCode\lxdzx/files/
2017-02-15 15:11:11,010 t_global_data.py[line:29] INFO -------Global_data init over
2017-02-15 15:11:11,357 t_global_data.py[line:26] INFO -------Global_data init
2017-02-15 15:11:11,357 t_global_data.py[line:28] INFO -------FILE_PATH F:\pythonCode\lxdzx/files/
2017-02-15 15:11:11,358 t_global_data.py[line:29] INFO -------Global_data init over
2017-02-15 15:16:03,068 t_global_data.py[line:26] INFO -------Global_data init
2017-02-15 15:16:03,068 t_global_data.py[line:28] INFO -------FILE_PATH F:\pythonCode\lxdzx/files/
2017-02-15 15:16:03,069 t_global_data.py[line:29] INFO -------Global_data init over
2017-02-15 15:16:14,013 t_global_data.py[line:26] INFO -------Global_data init
2017-02-15 15:16:14,013 t_global_data.py[line:28] INFO -------FILE_PATH F:\pythonCode\lxdzx/files/
2017-02-15 15:16:14,013 t_global_data.py[line:29] INFO -------Global_data init over
2017-02-15 15:16:26,017 t_global_data.py[line:26] INFO -------Global_data init
2017-02-15 15:16:26,017 t_global_data.py[line:28] INFO -------FILE_PATH F:\pythonCode\lxdzx/files/
2017-02-15 15:16:26,019 t_global_data.py[line:29] INFO -------Global_data init over
2017-02-15 15:16:29,688 t_global_data.py[line:26] INFO -------Global_data init
2017-02-15 15:16:29,688 t_global_data.py[line:28] INFO -------FILE_PATH F:\pythonCode\lxdzx/files/
2017-02-15 15:16:29,690 t_global_data.py[line:29] INFO -------Global_data init over
2017-02-15 15:16:46,868 t_global_data.py[line:26] INFO -------Global_data init
2017-02-15 15:16:46,868 t_global_data.py[line:28] INFO -------FILE_PATH F:\pythonCode\lxdzx/files/
2017-02-15 15:16:46,868 t_global_data.py[line:29] INFO -------Global_data init over
2017-02-15 15:16:58,852 t_global_data.py[line:26] INFO -------Global_data init
2017-02-15 15:16:58,852 t_global_data.py[line:28] INFO -------FILE_PATH F:\pythonCode\lxdzx/files/
2017-02-15 15:16:58,854 t_global_data.py[line:29] INFO -------Global_data init over
2017-02-15 15:17:02,500 t_global_data.py[line:26] INFO -------Global_data init
2017-02-15 15:17:02,500 t_global_data.py[line:28] INFO -------FILE_PATH F:\pythonCode\lxdzx/files/
2017-02-15 15:17:02,500 t_global_data.py[line:29] INFO -------Global_data init over
2017-02-15 15:17:06,153 t_global_data.py[line:26] INFO -------Global_data init
2017-02-15 15:17:06,153 t_global_data.py[line:28] INFO -------FILE_PATH F:\pythonCode\lxdzx/files/
2017-02-15 15:17:06,154 t_global_data.py[line:29] INFO -------Global_data init over
2017-02-15 15:17:17,099 t_global_data.py[line:26] INFO -------Global_data init
2017-02-15 15:17:17,099 t_global_data.py[line:28] INFO -------FILE_PATH F:\pythonCode\lxdzx/files/
2017-02-15 15:17:17,099 t_global_data.py[line:29] INFO -------Global_data init over
2017-02-15 15:17:24,930 t_global_data.py[line:26] INFO -------Global_data init
2017-02-15 15:17:24,930 t_global_data.py[line:28] INFO -------FILE_PATH F:\pythonCode\lxdzx/files/
2017-02-15 15:17:24,930 t_global_data.py[line:29] INFO -------Global_data init over
2017-02-15 15:17:33,759 t_global_data.py[line:26] INFO -------Global_data init
2017-02-15 15:17:33,759 t_global_data.py[line:28] INFO -------FILE_PATH F:\pythonCode\lxdzx/files/
2017-02-15 15:17:33,763 t_global_data.py[line:29] INFO -------Global_data init over
2017-02-15 15:17:48,861 t_global_data.py[line:26] INFO -------Global_data init
2017-02-15 15:17:48,861 t_global_data.py[line:28] INFO -------FILE_PATH F:\pythonCode\lxdzx/files/
2017-02-15 15:17:48,862 t_global_data.py[line:29] INFO -------Global_data init over
2017-02-15 15:18:07,059 t_global_data.py[line:26] INFO -------Global_data init
2017-02-15 15:18:07,059 t_global_data.py[line:28] INFO -------FILE_PATH F:\pythonCode\lxdzx/files/
2017-02-15 15:18:07,059 t_global_data.py[line:29] INFO -------Global_data init over
2017-02-15 15:19:26,747 t_global_data.py[line:26] INFO -------Global_data init
2017-02-15 15:19:26,749 t_global_data.py[line:28] INFO -------FILE_PATH F:\pythonCode\lxdzx/files/
2017-02-15 15:19:26,749 t_global_data.py[line:29] INFO -------Global_data init over
2017-02-15 15:19:49,130 t_global_data.py[line:26] INFO -------Global_data init
2017-02-15 15:19:49,130 t_global_data.py[line:28] INFO -------FILE_PATH F:\pythonCode\lxdzx/files/
2017-02-15 15:19:49,130 t_global_data.py[line:29] INFO -------Global_data init over
2017-02-15 15:20:00,088 t_global_data.py[line:26] INFO -------Global_data init
2017-02-15 15:20:00,088 t_global_data.py[line:28] INFO -------FILE_PATH F:\pythonCode\lxdzx/files/
2017-02-15 15:20:00,088 t_global_data.py[line:29] INFO -------Global_data init over
2017-02-15 15:20:12,075 t_global_data.py[line:26] INFO -------Global_data init
2017-02-15 15:20:12,075 t_global_data.py[line:28] INFO -------FILE_PATH F:\pythonCode\lxdzx/files/
2017-02-15 15:20:12,075 t_global_data.py[line:29] INFO -------Global_data init over
2017-02-15 15:20:15,470 exception.py[line:124] ERROR Internal Server Error: /get_all_videos
Traceback (most recent call last):
  File "F:\Python27\lib\site-packages\django\core\handlers\exception.py", line 39, in inner
    response = get_response(request)
  File "F:\Python27\lib\site-packages\django\core\handlers\base.py", line 187, in _get_response
    response = self.process_exception_by_middleware(e, request)
  File "F:\Python27\lib\site-packages\django\core\handlers\base.py", line 185, in _get_response
    response = wrapped_callback(request, *callback_args, **callback_kwargs)
  File "F:\pythonCode\lxdzx\videos_manager\views.py", line 22, in t_get_all_videos
    logging.debug(TJsonTools.encode(db_res))
TypeError: unbound method encode() must be called with TJsonTools instance as first argument (got QuerySet instance instead)
2017-02-15 15:20:45,927 t_global_data.py[line:26] INFO -------Global_data init
2017-02-15 15:20:45,927 t_global_data.py[line:28] INFO -------FILE_PATH F:\pythonCode\lxdzx/files/
2017-02-15 15:20:45,927 t_global_data.py[line:29] INFO -------Global_data init over
2017-02-15 15:20:50,581 exception.py[line:124] ERROR Internal Server Error: /get_all_videos
Traceback (most recent call last):
  File "F:\Python27\lib\site-packages\django\core\handlers\exception.py", line 39, in inner
    response = get_response(request)
  File "F:\Python27\lib\site-packages\django\core\handlers\base.py", line 187, in _get_response
    response = self.process_exception_by_middleware(e, request)
  File "F:\Python27\lib\site-packages\django\core\handlers\base.py", line 185, in _get_response
    response = wrapped_callback(request, *callback_args, **callback_kwargs)
  File "F:\pythonCode\lxdzx\videos_manager\views.py", line 22, in t_get_all_videos
    logging.debug(TJsonTools.tJsonEncode(db_res))
  File "F:\pythonCode\lxdzx\tutils\tjson.py", line 50, in tJsonEncode
    str = TJsonTools().encode(obj)
  File "F:\Python27\lib\json\encoder.py", line 207, in encode
    chunks = self.iterencode(o, _one_shot=True)
  File "F:\Python27\lib\json\encoder.py", line 270, in iterencode
    return _iterencode(o, 0)
  File "F:\pythonCode\lxdzx\tutils\tjson.py", line 28, in default
    js_encode.update(obj.__dict__)
AttributeError: 'set' object has no attribute '__dict__'
2017-02-15 15:21:40,542 t_global_data.py[line:26] INFO -------Global_data init
2017-02-15 15:21:40,543 t_global_data.py[line:28] INFO -------FILE_PATH F:\pythonCode\lxdzx/files/
2017-02-15 15:21:40,543 t_global_data.py[line:29] INFO -------Global_data init over
2017-02-15 15:21:42,934 exception.py[line:124] ERROR Internal Server Error: /get_all_videos
Traceback (most recent call last):
  File "F:\Python27\lib\site-packages\django\core\handlers\exception.py", line 39, in inner
    response = get_response(request)
  File "F:\Python27\lib\site-packages\django\core\handlers\base.py", line 187, in _get_response
    response = self.process_exception_by_middleware(e, request)
  File "F:\Python27\lib\site-packages\django\core\handlers\base.py", line 185, in _get_response
    response = wrapped_callback(request, *callback_args, **callback_kwargs)
  File "F:\pythonCode\lxdzx\videos_manager\views.py", line 22, in t_get_all_videos
    logging.debug(TJsonTools.tJsonEncode(db_res))
  File "F:\pythonCode\lxdzx\tutils\tjson.py", line 50, in tJsonEncode
    str = TJsonTools().encode(obj)
  File "F:\Python27\lib\json\encoder.py", line 207, in encode
    chunks = self.iterencode(o, _one_shot=True)
  File "F:\Python27\lib\json\encoder.py", line 270, in iterencode
    return _iterencode(o, 0)
  File "F:\pythonCode\lxdzx\tutils\tjson.py", line 28, in default
    js_encode.update(obj.__dict__)
AttributeError: 'set' object has no attribute '__dict__'
2017-02-15 15:21:51,549 t_global_data.py[line:26] INFO -------Global_data init
2017-02-15 15:21:51,549 t_global_data.py[line:28] INFO -------FILE_PATH F:\pythonCode\lxdzx/files/
2017-02-15 15:21:51,551 t_global_data.py[line:29] INFO -------Global_data init over
2017-02-15 15:21:52,232 exception.py[line:124] ERROR Internal Server Error: /get_all_videos
Traceback (most recent call last):
  File "F:\Python27\lib\site-packages\django\core\handlers\exception.py", line 39, in inner
    response = get_response(request)
  File "F:\Python27\lib\site-packages\django\core\handlers\base.py", line 187, in _get_response
    response = self.process_exception_by_middleware(e, request)
  File "F:\Python27\lib\site-packages\django\core\handlers\base.py", line 185, in _get_response
    response = wrapped_callback(request, *callback_args, **callback_kwargs)
  File "F:\pythonCode\lxdzx\videos_manager\views.py", line 22, in t_get_all_videos
    logging.debug(TJsonTools.tJsonEncode(db_res))
  File "F:\pythonCode\lxdzx\tutils\tjson.py", line 50, in tJsonEncode
    str = TJsonTools().encode(obj)
  File "F:\Python27\lib\json\encoder.py", line 207, in encode
    chunks = self.iterencode(o, _one_shot=True)
  File "F:\Python27\lib\json\encoder.py", line 270, in iterencode
    return _iterencode(o, 0)
  File "F:\pythonCode\lxdzx\tutils\tjson.py", line 28, in default
    js_encode.update(obj.__dict__)
AttributeError: 'set' object has no attribute '__dict__'
2017-02-15 15:22:12,891 t_global_data.py[line:26] INFO -------Global_data init
2017-02-15 15:22:12,891 t_global_data.py[line:28] INFO -------FILE_PATH F:\pythonCode\lxdzx/files/
2017-02-15 15:22:12,891 t_global_data.py[line:29] INFO -------Global_data init over
2017-02-15 15:22:16,556 t_global_data.py[line:26] INFO -------Global_data init
2017-02-15 15:22:16,556 t_global_data.py[line:28] INFO -------FILE_PATH F:\pythonCode\lxdzx/files/
2017-02-15 15:22:16,558 t_global_data.py[line:29] INFO -------Global_data init over
2017-02-15 15:22:38,953 t_global_data.py[line:26] INFO -------Global_data init
2017-02-15 15:22:38,953 t_global_data.py[line:28] INFO -------FILE_PATH F:\pythonCode\lxdzx/files/
2017-02-15 15:22:38,953 t_global_data.py[line:29] INFO -------Global_data init over
2017-02-15 15:22:41,698 exception.py[line:124] ERROR Internal Server Error: /get_all_videos
Traceback (most recent call last):
  File "F:\Python27\lib\site-packages\django\core\handlers\exception.py", line 39, in inner
    response = get_response(request)
  File "F:\Python27\lib\site-packages\django\core\handlers\base.py", line 187, in _get_response
    response = self.process_exception_by_middleware(e, request)
  File "F:\Python27\lib\site-packages\django\core\handlers\base.py", line 185, in _get_response
    response = wrapped_callback(request, *callback_args, **callback_kwargs)
  File "F:\pythonCode\lxdzx\videos_manager\views.py", line 23, in t_get_all_videos
    logging.debug(TJsonTools.tJsonEncode(item))
  File "F:\pythonCode\lxdzx\tutils\tjson.py", line 50, in tJsonEncode
    str = TJsonTools().encode(obj)
  File "F:\Python27\lib\json\encoder.py", line 207, in encode
    chunks = self.iterencode(o, _one_shot=True)
  File "F:\Python27\lib\json\encoder.py", line 270, in iterencode
    return _iterencode(o, 0)
  File "F:\pythonCode\lxdzx\tutils\tjson.py", line 28, in default
    js_encode.update(obj.__dict__)
AttributeError: 'datetime.datetime' object has no attribute '__dict__'
2017-02-15 15:23:19,061 t_global_data.py[line:26] INFO -------Global_data init
2017-02-15 15:23:19,062 t_global_data.py[line:28] INFO -------FILE_PATH F:\pythonCode\lxdzx/files/
2017-02-15 15:23:19,062 t_global_data.py[line:29] INFO -------Global_data init over
2017-02-15 15:23:24,792 t_global_data.py[line:26] INFO -------Global_data init
2017-02-15 15:23:24,793 t_global_data.py[line:28] INFO -------FILE_PATH F:\pythonCode\lxdzx/files/
2017-02-15 15:23:24,793 t_global_data.py[line:29] INFO -------Global_data init over
2017-02-15 15:25:04,109 t_global_data.py[line:26] INFO -------Global_data init
2017-02-15 15:25:04,111 t_global_data.py[line:28] INFO -------FILE_PATH F:\pythonCode\lxdzx/files/
2017-02-15 15:25:04,111 t_global_data.py[line:29] INFO -------Global_data init over
2017-02-15 15:25:05,767 t_global_data.py[line:26] INFO -------Global_data init
2017-02-15 15:25:05,767 t_global_data.py[line:28] INFO -------FILE_PATH F:\pythonCode\lxdzx/files/
2017-02-15 15:25:05,769 t_global_data.py[line:29] INFO -------Global_data init over
2017-02-15 15:25:09,448 t_global_data.py[line:26] INFO -------Global_data init
2017-02-15 15:25:09,450 t_global_data.py[line:28] INFO -------FILE_PATH F:\pythonCode\lxdzx/files/
2017-02-15 15:25:09,450 t_global_data.py[line:29] INFO -------Global_data init over
2017-02-15 15:27:57,551 exception.py[line:124] ERROR Internal Server Error: /get_all_videos
Traceback (most recent call last):
  File "F:\Python27\lib\site-packages\django\core\handlers\exception.py", line 39, in inner
    response = get_response(request)
  File "F:\Python27\lib\site-packages\django\core\handlers\base.py", line 187, in _get_response
    response = self.process_exception_by_middleware(e, request)
  File "F:\Python27\lib\site-packages\django\core\handlers\base.py", line 185, in _get_response
    response = wrapped_callback(request, *callback_args, **callback_kwargs)
  File "F:\pythonCode\lxdzx\videos_manager\views.py", line 26, in t_get_all_videos
    logging.debug(TJsonTools.tJsonEncode(item))
  File "F:\pythonCode\lxdzx\tutils\tjson.py", line 48, in tJsonEncode
    str = TJsonTools().encode(obj)
  File "F:\Python27\lib\json\encoder.py", line 207, in encode
    chunks = self.iterencode(o, _one_shot=True)
  File "F:\Python27\lib\json\encoder.py", line 270, in iterencode
    return _iterencode(o, 0)
  File "F:\pythonCode\lxdzx\tutils\tjson.py", line 26, in default
    js_encode.update(obj.__dict__)
AttributeError: 'datetime.datetime' object has no attribute '__dict__'
2017-02-15 15:35:06,585 t_global_data.py[line:26] INFO -------Global_data init
2017-02-15 15:35:06,585 t_global_data.py[line:28] INFO -------FILE_PATH F:\pythonCode\lxdzx/files/
2017-02-15 15:35:06,585 t_global_data.py[line:29] INFO -------Global_data init over
2017-02-15 15:35:11,230 t_global_data.py[line:26] INFO -------Global_data init
2017-02-15 15:35:11,232 t_global_data.py[line:28] INFO -------FILE_PATH F:\pythonCode\lxdzx/files/
2017-02-15 15:35:11,232 t_global_data.py[line:29] INFO -------Global_data init over
2017-02-15 15:41:42,319 t_global_data.py[line:26] INFO -------Global_data init
2017-02-15 15:41:42,321 t_global_data.py[line:28] INFO -------FILE_PATH F:\pythonCode\lxdzx/files/
2017-02-15 15:41:42,321 t_global_data.py[line:29] INFO -------Global_data init over
2017-02-15 15:42:28,628 t_global_data.py[line:26] INFO -------Global_data init
2017-02-15 15:42:28,628 t_global_data.py[line:28] INFO -------FILE_PATH F:\pythonCode\lxdzx/files/
2017-02-15 15:42:28,628 t_global_data.py[line:29] INFO -------Global_data init over
2017-02-15 15:42:31,246 t_global_data.py[line:26] INFO -------Global_data init
2017-02-15 15:42:31,246 t_global_data.py[line:28] INFO -------FILE_PATH F:\pythonCode\lxdzx/files/
2017-02-15 15:42:31,246 t_global_data.py[line:29] INFO -------Global_data init over
2017-02-15 15:42:35,977 t_global_data.py[line:26] INFO -------Global_data init
2017-02-15 15:42:35,977 t_global_data.py[line:28] INFO -------FILE_PATH F:\pythonCode\lxdzx/files/
2017-02-15 15:42:35,977 t_global_data.py[line:29] INFO -------Global_data init over
2017-02-15 15:42:46,930 t_global_data.py[line:26] INFO -------Global_data init
2017-02-15 15:42:46,930 t_global_data.py[line:28] INFO -------FILE_PATH F:\pythonCode\lxdzx/files/
2017-02-15 15:42:46,930 t_global_data.py[line:29] INFO -------Global_data init over
2017-02-15 15:42:55,813 t_global_data.py[line:26] INFO -------Global_data init
2017-02-15 15:42:55,813 t_global_data.py[line:28] INFO -------FILE_PATH F:\pythonCode\lxdzx/files/
2017-02-15 15:42:55,813 t_global_data.py[line:29] INFO -------Global_data init over
2017-02-15 15:43:00,545 t_global_data.py[line:26] INFO -------Global_data init
2017-02-15 15:43:00,545 t_global_data.py[line:28] INFO -------FILE_PATH F:\pythonCode\lxdzx/files/
2017-02-15 15:43:00,545 t_global_data.py[line:29] INFO -------Global_data init over
2017-02-15 15:43:02,075 t_global_data.py[line:26] INFO -------Global_data init
2017-02-15 15:43:02,075 t_global_data.py[line:28] INFO -------FILE_PATH F:\pythonCode\lxdzx/files/
2017-02-15 15:43:02,076 t_global_data.py[line:29] INFO -------Global_data init over
2017-02-15 15:43:05,727 t_global_data.py[line:26] INFO -------Global_data init
2017-02-15 15:43:05,727 t_global_data.py[line:28] INFO -------FILE_PATH F:\pythonCode\lxdzx/files/
2017-02-15 15:43:05,729 t_global_data.py[line:29] INFO -------Global_data init over
2017-02-15 15:43:12,523 t_global_data.py[line:26] INFO -------Global_data init
2017-02-15 15:43:12,523 t_global_data.py[line:28] INFO -------FILE_PATH F:\pythonCode\lxdzx/files/
2017-02-15 15:43:12,523 t_global_data.py[line:29] INFO -------Global_data init over
2017-02-15 15:43:17,348 t_global_data.py[line:26] INFO -------Global_data init
2017-02-15 15:43:17,348 t_global_data.py[line:28] INFO -------FILE_PATH F:\pythonCode\lxdzx/files/
2017-02-15 15:43:17,349 t_global_data.py[line:29] INFO -------Global_data init over
2017-02-15 15:43:34,539 t_global_data.py[line:26] INFO -------Global_data init
2017-02-15 15:43:34,539 t_global_data.py[line:28] INFO -------FILE_PATH F:\pythonCode\lxdzx/files/
2017-02-15 15:43:34,539 t_global_data.py[line:29] INFO -------Global_data init over
2017-02-15 15:43:42,325 t_global_data.py[line:26] INFO -------Global_data init
2017-02-15 15:43:42,325 t_global_data.py[line:28] INFO -------FILE_PATH F:\pythonCode\lxdzx/files/
2017-02-15 15:43:42,325 t_global_data.py[line:29] INFO -------Global_data init over
2017-02-15 15:44:30,726 t_global_data.py[line:26] INFO -------Global_data init
2017-02-15 15:44:30,726 t_global_data.py[line:28] INFO -------FILE_PATH F:\pythonCode\lxdzx/files/
2017-02-15 15:44:30,726 t_global_data.py[line:29] INFO -------Global_data init over
2017-02-15 15:44:46,875 t_global_data.py[line:26] INFO -------Global_data init
2017-02-15 15:44:46,875 t_global_data.py[line:28] INFO -------FILE_PATH F:\pythonCode\lxdzx/files/
2017-02-15 15:44:46,875 t_global_data.py[line:29] INFO -------Global_data init over
2017-02-15 15:45:26,927 t_global_data.py[line:26] INFO -------Global_data init
2017-02-15 15:45:26,927 t_global_data.py[line:28] INFO -------FILE_PATH F:\pythonCode\lxdzx/files/
2017-02-15 15:45:26,928 t_global_data.py[line:29] INFO -------Global_data init over
2017-02-15 15:46:03,895 t_global_data.py[line:26] INFO -------Global_data init
2017-02-15 15:46:03,897 t_global_data.py[line:28] INFO -------FILE_PATH F:\pythonCode\lxdzx/files/
2017-02-15 15:46:03,897 t_global_data.py[line:29] INFO -------Global_data init over
2017-02-15 15:46:19,026 t_global_data.py[line:26] INFO -------Global_data init
2017-02-15 15:46:19,026 t_global_data.py[line:28] INFO -------FILE_PATH F:\pythonCode\lxdzx/files/
2017-02-15 15:46:19,028 t_global_data.py[line:29] INFO -------Global_data init over
2017-02-15 15:49:58,101 t_global_data.py[line:26] INFO -------Global_data init
2017-02-15 15:49:58,101 t_global_data.py[line:28] INFO -------FILE_PATH F:\pythonCode\lxdzx/files/
2017-02-15 15:49:58,101 t_global_data.py[line:29] INFO -------Global_data init over
2017-02-15 15:50:00,805 exception.py[line:124] ERROR Internal Server Error: /get_all_videos
Traceback (most recent call last):
  File "F:\Python27\lib\site-packages\django\core\handlers\exception.py", line 39, in inner
    response = get_response(request)
  File "F:\Python27\lib\site-packages\django\core\handlers\base.py", line 187, in _get_response
    response = self.process_exception_by_middleware(e, request)
  File "F:\Python27\lib\site-packages\django\core\handlers\base.py", line 185, in _get_response
    response = wrapped_callback(request, *callback_args, **callback_kwargs)
  File "F:\pythonCode\lxdzx\videos_manager\views.py", line 36, in t_get_all_videos
    logging.debug(TJsonTools.tJsonEncode(item))
  File "F:\pythonCode\lxdzx\tutils\tjson.py", line 48, in tJsonEncode
    str = TJsonTools().encode(obj)
  File "F:\Python27\lib\json\encoder.py", line 207, in encode
    chunks = self.iterencode(o, _one_shot=True)
  File "F:\Python27\lib\json\encoder.py", line 270, in iterencode
    return _iterencode(o, 0)
  File "F:\pythonCode\lxdzx\tutils\tjson.py", line 26, in default
    js_encode.update(obj.__dict__)
AttributeError: 'datetime.datetime' object has no attribute '__dict__'
2017-02-15 15:50:17,476 t_global_data.py[line:26] INFO -------Global_data init
2017-02-15 15:50:17,476 t_global_data.py[line:28] INFO -------FILE_PATH F:\pythonCode\lxdzx/files/
2017-02-15 15:50:17,476 t_global_data.py[line:29] INFO -------Global_data init over
2017-02-15 15:50:23,592 exception.py[line:124] ERROR Internal Server Error: /get_all_videos
Traceback (most recent call last):
  File "F:\Python27\lib\site-packages\django\core\handlers\exception.py", line 39, in inner
    response = get_response(request)
  File "F:\Python27\lib\site-packages\django\core\handlers\base.py", line 187, in _get_response
    response = self.process_exception_by_middleware(e, request)
  File "F:\Python27\lib\site-packages\django\core\handlers\base.py", line 185, in _get_response
    response = wrapped_callback(request, *callback_args, **callback_kwargs)
  File "F:\pythonCode\lxdzx\videos_manager\views.py", line 36, in t_get_all_videos
    logging.debug(TJsonTools.tJsonEncode(video))
  File "F:\pythonCode\lxdzx\tutils\tjson.py", line 48, in tJsonEncode
    str = TJsonTools().encode(obj)
  File "F:\Python27\lib\json\encoder.py", line 207, in encode
    chunks = self.iterencode(o, _one_shot=True)
  File "F:\Python27\lib\json\encoder.py", line 270, in iterencode
    return _iterencode(o, 0)
ValueError: Circular reference detected
2017-02-15 15:50:45,055 t_global_data.py[line:26] INFO -------Global_data init
2017-02-15 15:50:45,055 t_global_data.py[line:28] INFO -------FILE_PATH F:\pythonCode\lxdzx/files/
2017-02-15 15:50:45,056 t_global_data.py[line:29] INFO -------Global_data init over
2017-02-15 15:50:59,174 t_global_data.py[line:26] INFO -------Global_data init
2017-02-15 15:50:59,174 t_global_data.py[line:28] INFO -------FILE_PATH F:\pythonCode\lxdzx/files/
2017-02-15 15:50:59,174 t_global_data.py[line:29] INFO -------Global_data init over
2017-02-15 15:51:03,867 t_global_data.py[line:26] INFO -------Global_data init
2017-02-15 15:51:03,868 t_global_data.py[line:28] INFO -------FILE_PATH F:\pythonCode\lxdzx/files/
2017-02-15 15:51:03,868 t_global_data.py[line:29] INFO -------Global_data init over
2017-02-15 15:51:07,819 exception.py[line:124] ERROR Internal Server Error: /get_all_videos
Traceback (most recent call last):
  File "F:\Python27\lib\site-packages\django\core\handlers\exception.py", line 39, in inner
    response = get_response(request)
  File "F:\Python27\lib\site-packages\django\core\handlers\base.py", line 187, in _get_response
    response = self.process_exception_by_middleware(e, request)
  File "F:\Python27\lib\site-packages\django\core\handlers\base.py", line 185, in _get_response
    response = wrapped_callback(request, *callback_args, **callback_kwargs)
  File "F:\pythonCode\lxdzx\videos_manager\views.py", line 36, in t_get_all_videos
    logging.debug(TJsonTools.tJsonEncode(video))
  File "F:\pythonCode\lxdzx\tutils\tjson.py", line 48, in tJsonEncode
    str = TJsonTools().encode(obj)
  File "F:\Python27\lib\json\encoder.py", line 207, in encode
    chunks = self.iterencode(o, _one_shot=True)
  File "F:\Python27\lib\json\encoder.py", line 270, in iterencode
    return _iterencode(o, 0)
  File "F:\pythonCode\lxdzx\tutils\tjson.py", line 26, in default
    js_encode.update(obj.__dict__)
AttributeError: 'datetime.datetime' object has no attribute '__dict__'
2017-02-15 15:51:25,207 t_global_data.py[line:26] INFO -------Global_data init
2017-02-15 15:51:25,207 t_global_data.py[line:28] INFO -------FILE_PATH F:\pythonCode\lxdzx/files/
2017-02-15 15:51:25,207 t_global_data.py[line:29] INFO -------Global_data init over
2017-02-15 15:51:34,119 t_global_data.py[line:26] INFO -------Global_data init
2017-02-15 15:51:34,119 t_global_data.py[line:28] INFO -------FILE_PATH F:\pythonCode\lxdzx/files/
2017-02-15 15:51:34,119 t_global_data.py[line:29] INFO -------Global_data init over
2017-02-15 15:51:34,664 exception.py[line:124] ERROR Internal Server Error: /get_all_videos
Traceback (most recent call last):
  File "F:\Python27\lib\site-packages\django\core\handlers\exception.py", line 39, in inner
    response = get_response(request)
  File "F:\Python27\lib\site-packages\django\core\handlers\base.py", line 187, in _get_response
    response = self.process_exception_by_middleware(e, request)
  File "F:\Python27\lib\site-packages\django\core\handlers\base.py", line 185, in _get_response
    response = wrapped_callback(request, *callback_args, **callback_kwargs)
  File "F:\pythonCode\lxdzx\videos_manager\views.py", line 36, in t_get_all_videos
    logging.debug(TJsonTools.tJsonEncode(video))
  File "F:\pythonCode\lxdzx\tutils\tjson.py", line 48, in tJsonEncode
    str = TJsonTools().encode(obj)
  File "F:\Python27\lib\json\encoder.py", line 207, in encode
    chunks = self.iterencode(o, _one_shot=True)
  File "F:\Python27\lib\json\encoder.py", line 270, in iterencode
    return _iterencode(o, 0)
  File "F:\pythonCode\lxdzx\tutils\tjson.py", line 26, in default
    js_encode.update(obj.__dict__)
AttributeError: 'datetime.datetime' object has no attribute '__dict__'
2017-02-15 15:52:12,081 t_global_data.py[line:26] INFO -------Global_data init
2017-02-15 15:52:12,082 t_global_data.py[line:28] INFO -------FILE_PATH F:\pythonCode\lxdzx/files/
2017-02-15 15:52:12,082 t_global_data.py[line:29] INFO -------Global_data init over
2017-02-15 15:53:23,335 exception.py[line:124] ERROR Internal Server Error: /get_all_videos
Traceback (most recent call last):
  File "F:\Python27\lib\site-packages\django\core\handlers\exception.py", line 39, in inner
    response = get_response(request)
  File "F:\Python27\lib\site-packages\django\core\handlers\base.py", line 187, in _get_response
    response = self.process_exception_by_middleware(e, request)
  File "F:\Python27\lib\site-packages\django\core\handlers\base.py", line 185, in _get_response
    response = wrapped_callback(request, *callback_args, **callback_kwargs)
  File "F:\pythonCode\lxdzx\videos_manager\views.py", line 36, in t_get_all_videos
    logging.debug(TJsonTools.tJsonEncode(video))
  File "F:\pythonCode\lxdzx\tutils\tjson.py", line 48, in tJsonEncode
    str = TJsonTools().encode(obj)
  File "F:\Python27\lib\json\encoder.py", line 207, in encode
    chunks = self.iterencode(o, _one_shot=True)
  File "F:\Python27\lib\json\encoder.py", line 270, in iterencode
    return _iterencode(o, 0)
  File "F:\pythonCode\lxdzx\tutils\tjson.py", line 26, in default
    js_encode.update(obj.__dict__)
AttributeError: 'datetime.datetime' object has no attribute '__dict__'
2017-02-15 15:53:23,519 t_global_data.py[line:26] INFO -------Global_data init
2017-02-15 15:53:23,519 t_global_data.py[line:28] INFO -------FILE_PATH F:\pythonCode\lxdzx/files/
2017-02-15 15:53:23,519 t_global_data.py[line:29] INFO -------Global_data init over
2017-02-15 16:07:27,401 t_global_data.py[line:26] INFO -------Global_data init
2017-02-15 16:07:27,401 t_global_data.py[line:28] INFO -------FILE_PATH F:\pythonCode\lxdzx/files/
2017-02-15 16:07:27,401 t_global_data.py[line:29] INFO -------Global_data init over
2017-02-15 16:07:36,272 t_global_data.py[line:26] INFO -------Global_data init
2017-02-15 16:07:36,272 t_global_data.py[line:28] INFO -------FILE_PATH F:\pythonCode\lxdzx/files/
2017-02-15 16:07:36,272 t_global_data.py[line:29] INFO -------Global_data init over
2017-02-15 16:07:39,512 t_global_data.py[line:26] INFO -------Global_data init
2017-02-15 16:07:39,512 t_global_data.py[line:28] INFO -------FILE_PATH F:\pythonCode\lxdzx/files/
2017-02-15 16:07:39,513 t_global_data.py[line:29] INFO -------Global_data init over
2017-02-15 16:08:52,864 t_global_data.py[line:26] INFO -------Global_data init
2017-02-15 16:08:52,864 t_global_data.py[line:28] INFO -------FILE_PATH F:\pythonCode\lxdzx/files/
2017-02-15 16:08:52,864 t_global_data.py[line:29] INFO -------Global_data init over
2017-02-15 16:09:12,142 t_global_data.py[line:26] INFO -------Global_data init
2017-02-15 16:09:12,142 t_global_data.py[line:28] INFO -------FILE_PATH F:\pythonCode\lxdzx/files/
2017-02-15 16:09:12,142 t_global_data.py[line:29] INFO -------Global_data init over
2017-02-15 16:09:29,260 t_global_data.py[line:26] INFO -------Global_data init
2017-02-15 16:09:29,260 t_global_data.py[line:28] INFO -------FILE_PATH F:\pythonCode\lxdzx/files/
2017-02-15 16:09:29,260 t_global_data.py[line:29] INFO -------Global_data init over
2017-02-15 16:09:42,292 t_global_data.py[line:26] INFO -------Global_data init
2017-02-15 16:09:42,292 t_global_data.py[line:28] INFO -------FILE_PATH F:\pythonCode\lxdzx/files/
2017-02-15 16:09:42,292 t_global_data.py[line:29] INFO -------Global_data init over
2017-02-15 16:09:52,210 t_global_data.py[line:26] INFO -------Global_data init
2017-02-15 16:09:52,210 t_global_data.py[line:28] INFO -------FILE_PATH F:\pythonCode\lxdzx/files/
2017-02-15 16:09:52,210 t_global_data.py[line:29] INFO -------Global_data init over
2017-02-15 16:09:59,012 t_global_data.py[line:26] INFO -------Global_data init
2017-02-15 16:09:59,013 t_global_data.py[line:28] INFO -------FILE_PATH F:\pythonCode\lxdzx/files/
2017-02-15 16:09:59,013 t_global_data.py[line:29] INFO -------Global_data init over
2017-02-15 16:10:19,326 t_global_data.py[line:26] INFO -------Global_data init
2017-02-15 16:10:19,328 t_global_data.py[line:28] INFO -------FILE_PATH F:\pythonCode\lxdzx/files/
2017-02-15 16:10:19,328 t_global_data.py[line:29] INFO -------Global_data init over
2017-02-15 16:10:32,417 t_global_data.py[line:26] INFO -------Global_data init
2017-02-15 16:10:32,417 t_global_data.py[line:28] INFO -------FILE_PATH F:\pythonCode\lxdzx/files/
2017-02-15 16:10:32,417 t_global_data.py[line:29] INFO -------Global_data init over
2017-02-15 16:10:46,513 t_global_data.py[line:26] INFO -------Global_data init
2017-02-15 16:10:46,513 t_global_data.py[line:28] INFO -------FILE_PATH F:\pythonCode\lxdzx/files/
2017-02-15 16:10:46,513 t_global_data.py[line:29] INFO -------Global_data init over
2017-02-15 16:10:46,928 exception.py[line:124] ERROR Internal Server Error: /get_all_videos
Traceback (most recent call last):
  File "F:\Python27\lib\site-packages\django\core\handlers\exception.py", line 39, in inner
    response = get_response(request)
  File "F:\Python27\lib\site-packages\django\core\handlers\base.py", line 187, in _get_response
    response = self.process_exception_by_middleware(e, request)
  File "F:\Python27\lib\site-packages\django\core\handlers\base.py", line 185, in _get_response
    response = wrapped_callback(request, *callback_args, **callback_kwargs)
  File "F:\pythonCode\lxdzx\videos_manager\views.py", line 37, in t_get_all_videos
    logging.debug(TJsonTools.tJsonEncode(video))
  File "F:\pythonCode\lxdzx\tutils\tjson.py", line 49, in tJsonEncode
    str = TJsonTools().encode(obj)
  File "F:\Python27\lib\json\encoder.py", line 207, in encode
    chunks = self.iterencode(o, _one_shot=True)
  File "F:\Python27\lib\json\encoder.py", line 270, in iterencode
    return _iterencode(o, 0)
ValueError: Circular reference detected
2017-02-15 16:10:56,466 t_global_data.py[line:26] INFO -------Global_data init
2017-02-15 16:10:56,466 t_global_data.py[line:28] INFO -------FILE_PATH F:\pythonCode\lxdzx/files/
2017-02-15 16:10:56,466 t_global_data.py[line:29] INFO -------Global_data init over
2017-02-15 16:10:57,275 exception.py[line:124] ERROR Internal Server Error: /get_all_videos
Traceback (most recent call last):
  File "F:\Python27\lib\site-packages\django\core\handlers\exception.py", line 39, in inner
    response = get_response(request)
  File "F:\Python27\lib\site-packages\django\core\handlers\base.py", line 187, in _get_response
    response = self.process_exception_by_middleware(e, request)
  File "F:\Python27\lib\site-packages\django\core\handlers\base.py", line 185, in _get_response
    response = wrapped_callback(request, *callback_args, **callback_kwargs)
  File "F:\pythonCode\lxdzx\videos_manager\views.py", line 37, in t_get_all_videos
    logging.debug(TJsonTools.tJsonEncode(video))
  File "F:\pythonCode\lxdzx\tutils\tjson.py", line 49, in tJsonEncode
    str = TJsonTools().encode(obj)
  File "F:\Python27\lib\json\encoder.py", line 207, in encode
    chunks = self.iterencode(o, _one_shot=True)
  File "F:\Python27\lib\json\encoder.py", line 270, in iterencode
    return _iterencode(o, 0)
ValueError: Circular reference detected
2017-02-15 16:11:03,158 exception.py[line:124] ERROR Internal Server Error: /get_all_videos
Traceback (most recent call last):
  File "F:\Python27\lib\site-packages\django\core\handlers\exception.py", line 39, in inner
    response = get_response(request)
  File "F:\Python27\lib\site-packages\django\core\handlers\base.py", line 187, in _get_response
    response = self.process_exception_by_middleware(e, request)
  File "F:\Python27\lib\site-packages\django\core\handlers\base.py", line 185, in _get_response
    response = wrapped_callback(request, *callback_args, **callback_kwargs)
  File "F:\pythonCode\lxdzx\videos_manager\views.py", line 37, in t_get_all_videos
    logging.debug(TJsonTools.tJsonEncode(video))
  File "F:\pythonCode\lxdzx\tutils\tjson.py", line 49, in tJsonEncode
    str = TJsonTools().encode(obj)
  File "F:\Python27\lib\json\encoder.py", line 207, in encode
    chunks = self.iterencode(o, _one_shot=True)
  File "F:\Python27\lib\json\encoder.py", line 270, in iterencode
    return _iterencode(o, 0)
ValueError: Circular reference detected
2017-02-15 16:11:03,345 t_global_data.py[line:26] INFO -------Global_data init
2017-02-15 16:11:03,345 t_global_data.py[line:28] INFO -------FILE_PATH F:\pythonCode\lxdzx/files/
2017-02-15 16:11:03,345 t_global_data.py[line:29] INFO -------Global_data init over
2017-02-15 16:13:54,908 t_global_data.py[line:26] INFO -------Global_data init
2017-02-15 16:13:54,908 t_global_data.py[line:28] INFO -------FILE_PATH F:\pythonCode\lxdzx/files/
2017-02-15 16:13:54,908 t_global_data.py[line:29] INFO -------Global_data init over
2017-02-15 16:13:55,246 t_global_data.py[line:26] INFO -------Global_data init
2017-02-15 16:13:55,246 t_global_data.py[line:28] INFO -------FILE_PATH F:\pythonCode\lxdzx/files/
2017-02-15 16:13:55,246 t_global_data.py[line:29] INFO -------Global_data init over
2017-02-15 16:13:57,191 exception.py[line:124] ERROR Internal Server Error: /get_all_videos
Traceback (most recent call last):
  File "F:\Python27\lib\site-packages\django\core\handlers\exception.py", line 39, in inner
    response = get_response(request)
  File "F:\Python27\lib\site-packages\django\core\handlers\base.py", line 187, in _get_response
    response = self.process_exception_by_middleware(e, request)
  File "F:\Python27\lib\site-packages\django\core\handlers\base.py", line 185, in _get_response
    response = wrapped_callback(request, *callback_args, **callback_kwargs)
  File "F:\pythonCode\lxdzx\videos_manager\views.py", line 37, in t_get_all_videos
    logging.debug(TJsonTools.tJsonEncode(video))
  File "F:\pythonCode\lxdzx\tutils\tjson.py", line 49, in tJsonEncode
    str = TJsonTools().encode(obj)
  File "F:\Python27\lib\json\encoder.py", line 207, in encode
    chunks = self.iterencode(o, _one_shot=True)
  File "F:\Python27\lib\json\encoder.py", line 270, in iterencode
    return _iterencode(o, 0)
ValueError: Circular reference detected
2017-02-15 16:14:22,845 t_global_data.py[line:26] INFO -------Global_data init
2017-02-15 16:14:22,846 t_global_data.py[line:28] INFO -------FILE_PATH F:\pythonCode\lxdzx/files/
2017-02-15 16:14:22,846 t_global_data.py[line:29] INFO -------Global_data init over
2017-02-15 16:22:18,940 t_global_data.py[line:26] INFO -------Global_data init
2017-02-15 16:22:18,940 t_global_data.py[line:28] INFO -------FILE_PATH F:\pythonCode\lxdzx/files/
2017-02-15 16:22:18,940 t_global_data.py[line:29] INFO -------Global_data init over
2017-02-15 16:22:39,306 t_global_data.py[line:26] INFO -------Global_data init
2017-02-15 16:22:39,308 t_global_data.py[line:28] INFO -------FILE_PATH F:\pythonCode\lxdzx/files/
2017-02-15 16:22:39,308 t_global_data.py[line:29] INFO -------Global_data init over
2017-02-15 16:23:23,516 t_global_data.py[line:26] INFO -------Global_data init
2017-02-15 16:23:23,516 t_global_data.py[line:28] INFO -------FILE_PATH F:\pythonCode\lxdzx/files/
2017-02-15 16:23:23,516 t_global_data.py[line:29] INFO -------Global_data init over
2017-02-15 16:23:24,094 exception.py[line:124] ERROR Internal Server Error: /get_all_videos
Traceback (most recent call last):
  File "F:\Python27\lib\site-packages\django\core\handlers\exception.py", line 39, in inner
    response = get_response(request)
  File "F:\Python27\lib\site-packages\django\core\handlers\base.py", line 187, in _get_response
    response = self.process_exception_by_middleware(e, request)
  File "F:\Python27\lib\site-packages\django\core\handlers\base.py", line 185, in _get_response
    response = wrapped_callback(request, *callback_args, **callback_kwargs)
  File "F:\pythonCode\lxdzx\videos_manager\views.py", line 39, in t_get_all_videos
    res = render_to_response(TJsonTools.tJsonEncode(tj_videos))
  File "F:\Python27\lib\site-packages\django\shortcuts.py", line 21, in render_to_response
    content = loader.render_to_string(template_name, context, using=using)
  File "F:\Python27\lib\site-packages\django\template\loader.py", line 67, in render_to_string
    template = get_template(template_name, using=using)
  File "F:\Python27\lib\site-packages\django\template\loader.py", line 25, in get_template
    raise TemplateDoesNotExist(template_name, chain=chain)
TemplateDoesNotExist: [{"bak_data": "", "video_url": "http://pandafly.file.alimmdn.com/yg.mp4?t=1486430639869", "title": "\u9884\u544a", "keywords": "\u9884\u544a,", "pic_url": "recv/icon.jpg", "desc": "\u9884\u544a\u7247"}, {"bak_data": "", "video_url": "http://pandafly.file.alimmdn.com/%E5%88%9B%E4%B8%9A%E4%B8%A4%E5%9D%97%E9%92%B1.wmv?t=1474870821484", "title": "\u521b\u4e1a\u4e24\u5757\u94b1", "keywords": "\u9a9a\u6c14,", "pic_url": "recv/001.jpg", "desc": "\u5982\u4f55\u521b\u4e1a"}]
2017-02-15 16:24:02,546 t_global_data.py[line:26] INFO -------Global_data init
2017-02-15 16:24:02,546 t_global_data.py[line:28] INFO -------FILE_PATH F:\pythonCode\lxdzx/files/
2017-02-15 16:24:02,546 t_global_data.py[line:29] INFO -------Global_data init over
2017-02-15 16:24:43,667 t_global_data.py[line:26] INFO -------Global_data init
2017-02-15 16:24:43,667 t_global_data.py[line:28] INFO -------FILE_PATH F:\pythonCode\lxdzx/files/
2017-02-15 16:24:43,667 t_global_data.py[line:29] INFO -------Global_data init over
2017-02-15 16:29:14,693 t_global_data.py[line:26] INFO -------Global_data init
2017-02-15 16:29:14,693 t_global_data.py[line:28] INFO -------FILE_PATH F:\pythonCode\lxdzx/files/
2017-02-15 16:29:14,693 t_global_data.py[line:29] INFO -------Global_data init over
2017-02-15 16:29:29,779 t_global_data.py[line:26] INFO -------Global_data init
2017-02-15 16:29:29,779 t_global_data.py[line:28] INFO -------FILE_PATH F:\pythonCode\lxdzx/files/
2017-02-15 16:29:29,779 t_global_data.py[line:29] INFO -------Global_data init over
2017-02-15 16:29:46,966 t_global_data.py[line:26] INFO -------Global_data init
2017-02-15 16:29:46,966 t_global_data.py[line:28] INFO -------FILE_PATH F:\pythonCode\lxdzx/files/
2017-02-15 16:29:46,966 t_global_data.py[line:29] INFO -------Global_data init over
2017-02-15 16:32:01,821 t_global_data.py[line:26] INFO -------Global_data init
2017-02-15 16:32:01,822 t_global_data.py[line:28] INFO -------FILE_PATH F:\pythonCode\lxdzx/files/
2017-02-15 16:32:01,822 t_global_data.py[line:29] INFO -------Global_data init over
2017-02-15 16:41:03,740 t_global_data.py[line:26] INFO -------Global_data init
2017-02-15 16:41:03,740 t_global_data.py[line:28] INFO -------FILE_PATH F:\pythonCode\lxdzx/files/
2017-02-15 16:41:03,740 t_global_data.py[line:29] INFO -------Global_data init over
2017-02-15 16:41:08,447 t_global_data.py[line:26] INFO -------Global_data init
2017-02-15 16:41:08,447 t_global_data.py[line:28] INFO -------FILE_PATH F:\pythonCode\lxdzx/files/
2017-02-15 16:41:08,447 t_global_data.py[line:29] INFO -------Global_data init over
2017-02-15 16:41:12,095 t_global_data.py[line:26] INFO -------Global_data init
2017-02-15 16:41:12,095 t_global_data.py[line:28] INFO -------FILE_PATH F:\pythonCode\lxdzx/files/
2017-02-15 16:41:12,096 t_global_data.py[line:29] INFO -------Global_data init over
2017-02-15 16:42:31,655 t_global_data.py[line:26] INFO -------Global_data init
2017-02-15 16:42:31,655 t_global_data.py[line:28] INFO -------FILE_PATH F:\pythonCode\lxdzx/files/
2017-02-15 16:42:31,655 t_global_data.py[line:29] INFO -------Global_data init over
2017-02-15 16:43:15,871 t_global_data.py[line:26] INFO -------Global_data init
2017-02-15 16:43:15,871 t_global_data.py[line:28] INFO -------FILE_PATH F:\pythonCode\lxdzx/files/
2017-02-15 16:43:15,871 t_global_data.py[line:29] INFO -------Global_data init over
2017-02-15 16:43:29,931 t_global_data.py[line:26] INFO -------Global_data init
2017-02-15 16:43:29,931 t_global_data.py[line:28] INFO -------FILE_PATH F:\pythonCode\lxdzx/files/
2017-02-15 16:43:29,931 t_global_data.py[line:29] INFO -------Global_data init over
2017-02-15 16:43:31,474 t_global_data.py[line:26] INFO -------Global_data init
2017-02-15 16:43:31,474 t_global_data.py[line:28] INFO -------FILE_PATH F:\pythonCode\lxdzx/files/
2017-02-15 16:43:31,476 t_global_data.py[line:29] INFO -------Global_data init over
2017-02-15 16:43:41,365 t_global_data.py[line:26] INFO -------Global_data init
2017-02-15 16:43:41,365 t_global_data.py[line:28] INFO -------FILE_PATH F:\pythonCode\lxdzx/files/
2017-02-15 16:43:41,365 t_global_data.py[line:29] INFO -------Global_data init over
2017-02-15 16:43:45,276 exception.py[line:124] ERROR Internal Server Error: /get_all_videos
Traceback (most recent call last):
  File "F:\Python27\lib\site-packages\django\core\handlers\exception.py", line 39, in inner
    response = get_response(request)
  File "F:\Python27\lib\site-packages\django\core\handlers\base.py", line 187, in _get_response
    response = self.process_exception_by_middleware(e, request)
  File "F:\Python27\lib\site-packages\django\core\handlers\base.py", line 185, in _get_response
    response = wrapped_callback(request, *callback_args, **callback_kwargs)
  File "F:\pythonCode\lxdzx\videos_manager\views.py", line 38, in t_get_all_videos
    logging.debug(TJsonTools.tJsonEncode(video))
  File "F:\pythonCode\lxdzx\tutils\tjson.py", line 50, in tJsonEncode
    str =JSONDecoder._decode_uXXXX(TJsonTools().encode(obj))
AttributeError: type object 'JSONDecoder' has no attribute '_decode_uXXXX'
2017-02-15 16:44:19,367 t_global_data.py[line:26] INFO -------Global_data init
2017-02-15 16:44:19,367 t_global_data.py[line:28] INFO -------FILE_PATH F:\pythonCode\lxdzx/files/
2017-02-15 16:44:19,367 t_global_data.py[line:29] INFO -------Global_data init over
2017-02-15 16:44:23,257 exception.py[line:124] ERROR Internal Server Error: /get_all_videos
Traceback (most recent call last):
  File "F:\Python27\lib\site-packages\django\core\handlers\exception.py", line 39, in inner
    response = get_response(request)
  File "F:\Python27\lib\site-packages\django\core\handlers\base.py", line 187, in _get_response
    response = self.process_exception_by_middleware(e, request)
  File "F:\Python27\lib\site-packages\django\core\handlers\base.py", line 185, in _get_response
    response = wrapped_callback(request, *callback_args, **callback_kwargs)
  File "F:\pythonCode\lxdzx\videos_manager\views.py", line 38, in t_get_all_videos
    logging.debug(TJsonTools.tJsonEncode(video))
  File "F:\pythonCode\lxdzx\tutils\tjson.py", line 50, in tJsonEncode
    str =decoder._decode_uXXXX(TJsonTools().encode(obj))
NameError: global name 'decoder' is not defined
2017-02-15 16:44:35,523 t_global_data.py[line:26] INFO -------Global_data init
2017-02-15 16:44:35,523 t_global_data.py[line:28] INFO -------FILE_PATH F:\pythonCode\lxdzx/files/
2017-02-15 16:44:35,523 t_global_data.py[line:29] INFO -------Global_data init over
2017-02-15 16:44:42,305 t_global_data.py[line:26] INFO -------Global_data init
2017-02-15 16:44:42,306 t_global_data.py[line:28] INFO -------FILE_PATH F:\pythonCode\lxdzx/files/
2017-02-15 16:44:42,306 t_global_data.py[line:29] INFO -------Global_data init over
2017-02-15 16:44:45,046 exception.py[line:124] ERROR Internal Server Error: /get_all_videos
Traceback (most recent call last):
  File "F:\Python27\lib\site-packages\django\core\handlers\exception.py", line 39, in inner
    response = get_response(request)
  File "F:\Python27\lib\site-packages\django\core\handlers\base.py", line 187, in _get_response
    response = self.process_exception_by_middleware(e, request)
  File "F:\Python27\lib\site-packages\django\core\handlers\base.py", line 185, in _get_response
    response = wrapped_callback(request, *callback_args, **callback_kwargs)
  File "F:\pythonCode\lxdzx\videos_manager\views.py", line 38, in t_get_all_videos
    logging.debug(TJsonTools.tJsonEncode(video))
  File "F:\pythonCode\lxdzx\tutils\tjson.py", line 48, in tJsonEncode
    str =json.decoder._decode_uXXXX(TJsonTools().encode(obj))
TypeError: _decode_uXXXX() takes exactly 2 arguments (1 given)
2017-02-15 16:44:49,762 exception.py[line:124] ERROR Internal Server Error: /get_all_videos
Traceback (most recent call last):
  File "F:\Python27\lib\site-packages\django\core\handlers\exception.py", line 39, in inner
    response = get_response(request)
  File "F:\Python27\lib\site-packages\django\core\handlers\base.py", line 187, in _get_response
    response = self.process_exception_by_middleware(e, request)
  File "F:\Python27\lib\site-packages\django\core\handlers\base.py", line 185, in _get_response
    response = wrapped_callback(request, *callback_args, **callback_kwargs)
  File "F:\pythonCode\lxdzx\videos_manager\views.py", line 38, in t_get_all_videos
    logging.debug(TJsonTools.tJsonEncode(video))
  File "F:\pythonCode\lxdzx\tutils\tjson.py", line 48, in tJsonEncode
    str =json.decoder._decode_uXXXX(TJsonTools().encode(obj))
TypeError: _decode_uXXXX() takes exactly 2 arguments (1 given)
2017-02-15 16:45:05,727 t_global_data.py[line:26] INFO -------Global_data init
2017-02-15 16:45:05,729 t_global_data.py[line:28] INFO -------FILE_PATH F:\pythonCode\lxdzx/files/
2017-02-15 16:45:05,729 t_global_data.py[line:29] INFO -------Global_data init over
2017-02-15 16:45:07,250 exception.py[line:124] ERROR Internal Server Error: /get_all_videos
Traceback (most recent call last):
  File "F:\Python27\lib\site-packages\django\core\handlers\exception.py", line 39, in inner
    response = get_response(request)
  File "F:\Python27\lib\site-packages\django\core\handlers\base.py", line 187, in _get_response
    response = self.process_exception_by_middleware(e, request)
  File "F:\Python27\lib\site-packages\django\core\handlers\base.py", line 185, in _get_response
    response = wrapped_callback(request, *callback_args, **callback_kwargs)
  File "F:\pythonCode\lxdzx\videos_manager\views.py", line 38, in t_get_all_videos
    logging.debug(TJsonTools.tJsonEncode(video))
  File "F:\pythonCode\lxdzx\tutils\tjson.py", line 48, in tJsonEncode
    str =json.decoder._decode_uXXXX(TJsonTools().encode(obj),0)
  File "F:\Python27\lib\json\decoder.py", line 71, in _decode_uXXXX
    raise ValueError(errmsg(msg, s, pos))
ValueError: Invalid \uXXXX escape: line 1 column 1 (char 0)
2017-02-15 16:45:19,903 t_global_data.py[line:26] INFO -------Global_data init
2017-02-15 16:45:19,904 t_global_data.py[line:28] INFO -------FILE_PATH F:\pythonCode\lxdzx/files/
2017-02-15 16:45:19,904 t_global_data.py[line:29] INFO -------Global_data init over
2017-02-15 16:46:59,482 t_global_data.py[line:26] INFO -------Global_data init
2017-02-15 16:46:59,482 t_global_data.py[line:28] INFO -------FILE_PATH F:\pythonCode\lxdzx/files/
2017-02-15 16:46:59,483 t_global_data.py[line:29] INFO -------Global_data init over
2017-02-15 16:47:46,808 t_global_data.py[line:26] INFO -------Global_data init
2017-02-15 16:47:46,808 t_global_data.py[line:28] INFO -------FILE_PATH F:\pythonCode\lxdzx/files/
2017-02-15 16:47:46,809 t_global_data.py[line:29] INFO -------Global_data init over
2017-02-15 16:48:21,726 t_global_data.py[line:26] INFO -------Global_data init
2017-02-15 16:48:21,727 t_global_data.py[line:28] INFO -------FILE_PATH F:\pythonCode\lxdzx/files/
2017-02-15 16:48:21,727 t_global_data.py[line:29] INFO -------Global_data init over
2017-02-15 16:48:33,703 t_global_data.py[line:26] INFO -------Global_data init
2017-02-15 16:48:33,703 t_global_data.py[line:28] INFO -------FILE_PATH F:\pythonCode\lxdzx/files/
2017-02-15 16:48:33,703 t_global_data.py[line:29] INFO -------Global_data init over
2017-02-15 16:48:54,015 t_global_data.py[line:26] INFO -------Global_data init
2017-02-15 16:48:54,015 t_global_data.py[line:28] INFO -------FILE_PATH F:\pythonCode\lxdzx/files/
2017-02-15 16:48:54,016 t_global_data.py[line:29] INFO -------Global_data init over
2017-02-15 16:49:01,894 t_global_data.py[line:26] INFO -------Global_data init
2017-02-15 16:49:01,894 t_global_data.py[line:28] INFO -------FILE_PATH F:\pythonCode\lxdzx/files/
2017-02-15 16:49:01,894 t_global_data.py[line:29] INFO -------Global_data init over
2017-02-15 17:41:51,085 t_global_data.py[line:26] INFO -------Global_data init
2017-02-15 17:41:51,085 t_global_data.py[line:28] INFO -------FILE_PATH F:\pythonCode\lxdzx/files/
2017-02-15 17:41:51,085 t_global_data.py[line:29] INFO -------Global_data init over
2017-02-16 11:07:30,742 t_global_data.py[line:26] INFO -------Global_data init
2017-02-16 11:07:30,743 t_global_data.py[line:28] INFO -------FILE_PATH F:\pythonCode\lxdzx/files/
2017-02-16 11:07:30,743 t_global_data.py[line:29] INFO -------Global_data init over
2017-02-16 11:07:31,095 t_global_data.py[line:26] INFO -------Global_data init
2017-02-16 11:07:31,095 t_global_data.py[line:28] INFO -------FILE_PATH F:\pythonCode\lxdzx/files/
2017-02-16 11:07:31,095 t_global_data.py[line:29] INFO -------Global_data init over
2017-02-16 11:34:58,789 base.py[line:152] WARNING Not Found: /favicon.ico
2017-02-16 11:38:12,269 t_global_data.py[line:26] INFO -------Global_data init
2017-02-16 11:38:12,269 t_global_data.py[line:28] INFO -------FILE_PATH F:\pythonCode\lxdzx/files/
2017-02-16 11:38:12,269 t_global_data.py[line:29] INFO -------Global_data init over
2017-02-16 13:50:55,733 t_global_data.py[line:26] INFO -------Global_data init
2017-02-16 13:50:55,734 t_global_data.py[line:28] INFO -------FILE_PATH F:\pythonCode\lxdzx/files/
2017-02-16 13:50:55,734 t_global_data.py[line:29] INFO -------Global_data init over
2017-02-16 13:51:25,700 t_global_data.py[line:26] INFO -------Global_data init
2017-02-16 13:51:25,700 t_global_data.py[line:28] INFO -------FILE_PATH F:\pythonCode\lxdzx/files/
2017-02-16 13:51:25,700 t_global_data.py[line:29] INFO -------Global_data init over
2017-02-16 13:52:42,311 t_global_data.py[line:26] INFO -------Global_data init
2017-02-16 13:52:42,311 t_global_data.py[line:28] INFO -------FILE_PATH F:\pythonCode\lxdzx/files/
2017-02-16 13:52:42,312 t_global_data.py[line:29] INFO -------Global_data init over
2017-02-16 13:53:38,375 t_global_data.py[line:26] INFO -------Global_data init
2017-02-16 13:53:38,375 t_global_data.py[line:28] INFO -------FILE_PATH F:\pythonCode\lxdzx/files/
2017-02-16 13:53:38,375 t_global_data.py[line:29] INFO -------Global_data init over
2017-02-16 13:53:44,204 t_global_data.py[line:26] INFO -------Global_data init
2017-02-16 13:53:44,204 t_global_data.py[line:28] INFO -------FILE_PATH F:\pythonCode\lxdzx/files/
2017-02-16 13:53:44,204 t_global_data.py[line:29] INFO -------Global_data init over
2017-02-16 13:54:07,755 t_global_data.py[line:26] INFO -------Global_data init
2017-02-16 13:54:07,756 t_global_data.py[line:28] INFO -------FILE_PATH F:\pythonCode\lxdzx/files/
2017-02-16 13:54:07,756 t_global_data.py[line:29] INFO -------Global_data init over
2017-02-16 13:54:53,269 t_global_data.py[line:26] INFO -------Global_data init
2017-02-16 13:54:53,269 t_global_data.py[line:28] INFO -------FILE_PATH F:\pythonCode\lxdzx/files/
2017-02-16 13:54:53,269 t_global_data.py[line:29] INFO -------Global_data init over
2017-02-16 13:54:56,763 t_global_data.py[line:26] INFO -------Global_data init
2017-02-16 13:54:56,763 t_global_data.py[line:28] INFO -------FILE_PATH F:\pythonCode\lxdzx/files/
2017-02-16 13:54:56,763 t_global_data.py[line:29] INFO -------Global_data init over
2017-02-16 13:55:12,078 t_global_data.py[line:26] INFO -------Global_data init
2017-02-16 13:55:12,078 t_global_data.py[line:28] INFO -------FILE_PATH F:\pythonCode\lxdzx/files/
2017-02-16 13:55:12,079 t_global_data.py[line:29] INFO -------Global_data init over
2017-02-16 13:55:23,069 t_global_data.py[line:26] INFO -------Global_data init
2017-02-16 13:55:23,069 t_global_data.py[line:28] INFO -------FILE_PATH F:\pythonCode\lxdzx/files/
2017-02-16 13:55:23,071 t_global_data.py[line:29] INFO -------Global_data init over
2017-02-16 13:55:24,736 t_global_data.py[line:26] INFO -------Global_data init
2017-02-16 13:55:24,736 t_global_data.py[line:28] INFO -------FILE_PATH F:\pythonCode\lxdzx/files/
2017-02-16 13:55:24,737 t_global_data.py[line:29] INFO -------Global_data init over
2017-02-16 14:04:11,265 t_global_data.py[line:26] INFO -------Global_data init
2017-02-16 14:04:11,266 t_global_data.py[line:28] INFO -------FILE_PATH F:\pythonCode\lxdzx/files/
2017-02-16 14:04:11,266 t_global_data.py[line:29] INFO -------Global_data init over
2017-02-16 14:04:21,887 t_global_data.py[line:26] INFO -------Global_data init
2017-02-16 14:04:21,887 t_global_data.py[line:28] INFO -------FILE_PATH F:\pythonCode\lxdzx/files/
2017-02-16 14:04:21,888 t_global_data.py[line:29] INFO -------Global_data init over
2017-02-16 14:04:36,062 t_global_data.py[line:26] INFO -------Global_data init
2017-02-16 14:04:36,062 t_global_data.py[line:28] INFO -------FILE_PATH F:\pythonCode\lxdzx/files/
2017-02-16 14:04:36,063 t_global_data.py[line:29] INFO -------Global_data init over
2017-02-16 14:10:23,914 t_global_data.py[line:26] INFO -------Global_data init
2017-02-16 14:10:23,914 t_global_data.py[line:28] INFO -------FILE_PATH F:\pythonCode\lxdzx/files/
2017-02-16 14:10:23,914 t_global_data.py[line:29] INFO -------Global_data init over
2017-02-16 14:10:34,973 t_global_data.py[line:26] INFO -------Global_data init
2017-02-16 14:10:34,973 t_global_data.py[line:28] INFO -------FILE_PATH F:\pythonCode\lxdzx/files/
2017-02-16 14:10:34,973 t_global_data.py[line:29] INFO -------Global_data init over
2017-02-16 14:10:54,405 t_global_data.py[line:26] INFO -------Global_data init
2017-02-16 14:10:54,407 t_global_data.py[line:28] INFO -------FILE_PATH F:\pythonCode\lxdzx/files/
2017-02-16 14:10:54,407 t_global_data.py[line:29] INFO -------Global_data init over
2017-02-16 14:11:38,821 t_global_data.py[line:26] INFO -------Global_data init
2017-02-16 14:11:38,822 t_global_data.py[line:28] INFO -------FILE_PATH F:\pythonCode\lxdzx/files/
2017-02-16 14:11:38,822 t_global_data.py[line:29] INFO -------Global_data init over
2017-02-16 14:12:20,065 t_global_data.py[line:26] INFO -------Global_data init
2017-02-16 14:12:20,066 t_global_data.py[line:28] INFO -------FILE_PATH F:\pythonCode\lxdzx/files/
2017-02-16 14:12:20,066 t_global_data.py[line:29] INFO -------Global_data init over
2017-02-16 14:12:37,444 t_global_data.py[line:26] INFO -------Global_data init
2017-02-16 14:12:37,444 t_global_data.py[line:28] INFO -------FILE_PATH F:\pythonCode\lxdzx/files/
2017-02-16 14:12:37,446 t_global_data.py[line:29] INFO -------Global_data init over
2017-02-16 14:12:48,565 t_global_data.py[line:26] INFO -------Global_data init
2017-02-16 14:12:48,566 t_global_data.py[line:28] INFO -------FILE_PATH F:\pythonCode\lxdzx/files/
2017-02-16 14:12:48,566 t_global_data.py[line:29] INFO -------Global_data init over
2017-02-16 14:12:52,306 t_global_data.py[line:26] INFO -------Global_data init
2017-02-16 14:12:52,306 t_global_data.py[line:28] INFO -------FILE_PATH F:\pythonCode\lxdzx/files/
2017-02-16 14:12:52,306 t_global_data.py[line:29] INFO -------Global_data init over
2017-02-16 14:12:58,099 t_global_data.py[line:26] INFO -------Global_data init
2017-02-16 14:12:58,101 t_global_data.py[line:28] INFO -------FILE_PATH F:\pythonCode\lxdzx/files/
2017-02-16 14:12:58,101 t_global_data.py[line:29] INFO -------Global_data init over
2017-02-16 14:13:15,369 t_global_data.py[line:26] INFO -------Global_data init
2017-02-16 14:13:15,369 t_global_data.py[line:28] INFO -------FILE_PATH F:\pythonCode\lxdzx/files/
2017-02-16 14:13:15,369 t_global_data.py[line:29] INFO -------Global_data init over
2017-02-16 14:13:37,901 t_global_data.py[line:26] INFO -------Global_data init
2017-02-16 14:13:37,901 t_global_data.py[line:28] INFO -------FILE_PATH F:\pythonCode\lxdzx/files/
2017-02-16 14:13:37,901 t_global_data.py[line:29] INFO -------Global_data init over
2017-02-16 14:13:54,180 t_global_data.py[line:26] INFO -------Global_data init
2017-02-16 14:13:54,180 t_global_data.py[line:28] INFO -------FILE_PATH F:\pythonCode\lxdzx/files/
2017-02-16 14:13:54,180 t_global_data.py[line:29] INFO -------Global_data init over
2017-02-16 14:15:48,599 t_global_data.py[line:26] INFO -------Global_data init
2017-02-16 14:15:48,601 t_global_data.py[line:28] INFO -------FILE_PATH F:\pythonCode\lxdzx/files/
2017-02-16 14:15:48,601 t_global_data.py[line:29] INFO -------Global_data init over
2017-02-16 14:15:56,519 t_global_data.py[line:26] INFO -------Global_data init
2017-02-16 14:15:56,519 t_global_data.py[line:28] INFO -------FILE_PATH F:\pythonCode\lxdzx/files/
2017-02-16 14:15:56,519 t_global_data.py[line:29] INFO -------Global_data init over
2017-02-16 14:16:03,183 exception.py[line:124] ERROR Internal Server Error: /get_all_videos
Traceback (most recent call last):
  File "F:\Python27\lib\site-packages\django\core\handlers\exception.py", line 39, in inner
    response = get_response(request)
  File "F:\Python27\lib\site-packages\django\core\handlers\base.py", line 187, in _get_response
    response = self.process_exception_by_middleware(e, request)
  File "F:\Python27\lib\site-packages\django\core\handlers\base.py", line 185, in _get_response
    response = wrapped_callback(request, *callback_args, **callback_kwargs)
  File "F:\pythonCode\lxdzx\videos_manager\views.py", line 40, in t_get_all_videos
    res = HttpResponse(TJsonTools.tJsonEncode(tj_videos).decode('utf-8').encode('utf8'))
  File "F:\Python27\lib\encodings\utf_8.py", line 16, in decode
    return codecs.utf_8_decode(input, errors, True)
UnicodeEncodeError: 'ascii' codec can't encode characters in position 15-16: ordinal not in range(128)
2017-02-16 14:54:22,395 exception.py[line:124] ERROR Internal Server Error: /get_all_videos
Traceback (most recent call last):
  File "F:\Python27\lib\site-packages\django\core\handlers\exception.py", line 39, in inner
    response = get_response(request)
  File "F:\Python27\lib\site-packages\django\core\handlers\base.py", line 187, in _get_response
    response = self.process_exception_by_middleware(e, request)
  File "F:\Python27\lib\site-packages\django\core\handlers\base.py", line 185, in _get_response
    response = wrapped_callback(request, *callback_args, **callback_kwargs)
  File "F:\pythonCode\lxdzx\videos_manager\views.py", line 40, in t_get_all_videos
    res = HttpResponse(TJsonTools.tJsonEncode(tj_videos).decode('utf-8').encode('utf8'))
  File "F:\Python27\lib\encodings\utf_8.py", line 16, in decode
    return codecs.utf_8_decode(input, errors, True)
UnicodeEncodeError: 'ascii' codec can't encode characters in position 15-16: ordinal not in range(128)
2017-02-16 14:55:15,778 t_global_data.py[line:26] INFO -------Global_data init
2017-02-16 14:55:15,779 t_global_data.py[line:28] INFO -------FILE_PATH F:\pythonCode\lxdzx/files/
2017-02-16 14:55:15,779 t_global_data.py[line:29] INFO -------Global_data init over
2017-02-16 14:55:18,447 t_global_data.py[line:26] INFO -------Global_data init
2017-02-16 14:55:18,447 t_global_data.py[line:28] INFO -------FILE_PATH F:\pythonCode\lxdzx/files/
2017-02-16 14:55:18,447 t_global_data.py[line:29] INFO -------Global_data init over
2017-02-16 14:55:24,256 t_global_data.py[line:26] INFO -------Global_data init
2017-02-16 14:55:24,256 t_global_data.py[line:28] INFO -------FILE_PATH F:\pythonCode\lxdzx/files/
2017-02-16 14:55:24,256 t_global_data.py[line:29] INFO -------Global_data init over
2017-02-16 14:55:31,069 t_global_data.py[line:26] INFO -------Global_data init
2017-02-16 14:55:31,069 t_global_data.py[line:28] INFO -------FILE_PATH F:\pythonCode\lxdzx/files/
2017-02-16 14:55:31,069 t_global_data.py[line:29] INFO -------Global_data init over
2017-02-16 14:55:49,391 t_global_data.py[line:26] INFO -------Global_data init
2017-02-16 14:55:49,391 t_global_data.py[line:28] INFO -------FILE_PATH F:\pythonCode\lxdzx/files/
2017-02-16 14:55:49,391 t_global_data.py[line:29] INFO -------Global_data init over
2017-02-16 14:58:00,523 t_global_data.py[line:26] INFO -------Global_data init
2017-02-16 14:58:00,523 t_global_data.py[line:28] INFO -------FILE_PATH F:\pythonCode\lxdzx/files/
2017-02-16 14:58:00,525 t_global_data.py[line:29] INFO -------Global_data init over
2017-02-16 14:58:06,319 t_global_data.py[line:26] INFO -------Global_data init
2017-02-16 14:58:06,319 t_global_data.py[line:28] INFO -------FILE_PATH F:\pythonCode\lxdzx/files/
2017-02-16 14:58:06,319 t_global_data.py[line:29] INFO -------Global_data init over
2017-02-16 14:58:43,476 t_global_data.py[line:26] INFO -------Global_data init
2017-02-16 14:58:43,476 t_global_data.py[line:28] INFO -------FILE_PATH F:\pythonCode\lxdzx/files/
2017-02-16 14:58:43,476 t_global_data.py[line:29] INFO -------Global_data init over
2017-02-16 14:58:48,444 exception.py[line:124] ERROR Internal Server Error: /get_all_videos
Traceback (most recent call last):
  File "F:\Python27\lib\site-packages\django\core\handlers\exception.py", line 39, in inner
    response = get_response(request)
  File "F:\Python27\lib\site-packages\django\core\handlers\base.py", line 187, in _get_response
    response = self.process_exception_by_middleware(e, request)
  File "F:\Python27\lib\site-packages\django\core\handlers\base.py", line 185, in _get_response
    response = wrapped_callback(request, *callback_args, **callback_kwargs)
  File "F:\pythonCode\lxdzx\videos_manager\views.py", line 34, in t_get_all_videos
    video.upload_time = time.strftime("%Y-%m-%d",item.upload_time)   # 鏃堕棿
NameError: global name 'time' is not defined
2017-02-16 14:59:11,255 t_global_data.py[line:26] INFO -------Global_data init
2017-02-16 14:59:11,255 t_global_data.py[line:28] INFO -------FILE_PATH F:\pythonCode\lxdzx/files/
2017-02-16 14:59:11,255 t_global_data.py[line:29] INFO -------Global_data init over
2017-02-16 15:00:26,944 t_global_data.py[line:26] INFO -------Global_data init
2017-02-16 15:00:26,944 t_global_data.py[line:28] INFO -------FILE_PATH F:\pythonCode\lxdzx/files/
2017-02-16 15:00:26,944 t_global_data.py[line:29] INFO -------Global_data init over
2017-02-16 15:00:30,671 t_global_data.py[line:26] INFO -------Global_data init
2017-02-16 15:00:30,673 t_global_data.py[line:28] INFO -------FILE_PATH F:\pythonCode\lxdzx/files/
2017-02-16 15:00:30,673 t_global_data.py[line:29] INFO -------Global_data init over
2017-02-16 15:00:41,019 exception.py[line:124] ERROR Internal Server Error: /get_all_videos
Traceback (most recent call last):
  File "F:\Python27\lib\site-packages\django\core\handlers\exception.py", line 39, in inner
    response = get_response(request)
  File "F:\Python27\lib\site-packages\django\core\handlers\base.py", line 187, in _get_response
    response = self.process_exception_by_middleware(e, request)
  File "F:\Python27\lib\site-packages\django\core\handlers\base.py", line 185, in _get_response
    response = wrapped_callback(request, *callback_args, **callback_kwargs)
  File "F:\pythonCode\lxdzx\videos_manager\views.py", line 35, in t_get_all_videos
    video.upload_time = time.strftime("%Y-%m-%d",item.upload_time)   # 鏃堕棿
TypeError: argument must be 9-item sequence, not datetime.datetime
2017-02-16 15:03:49,131 t_global_data.py[line:26] INFO -------Global_data init
2017-02-16 15:03:49,131 t_global_data.py[line:28] INFO -------FILE_PATH F:\pythonCode\lxdzx/files/
2017-02-16 15:03:49,132 t_global_data.py[line:29] INFO -------Global_data init over
2017-02-16 15:03:49,482 t_global_data.py[line:26] INFO -------Global_data init
2017-02-16 15:03:49,483 t_global_data.py[line:28] INFO -------FILE_PATH F:\pythonCode\lxdzx/files/
2017-02-16 15:03:49,483 t_global_data.py[line:29] INFO -------Global_data init over
2017-02-16 15:03:51,267 exception.py[line:124] ERROR Internal Server Error: /get_all_videos
Traceback (most recent call last):
  File "F:\Python27\lib\site-packages\django\core\handlers\exception.py", line 39, in inner
    response = get_response(request)
  File "F:\Python27\lib\site-packages\django\core\handlers\base.py", line 187, in _get_response
    response = self.process_exception_by_middleware(e, request)
  File "F:\Python27\lib\site-packages\django\core\handlers\base.py", line 185, in _get_response
    response = wrapped_callback(request, *callback_args, **callback_kwargs)
  File "F:\pythonCode\lxdzx\videos_manager\views.py", line 35, in t_get_all_videos
    video.upload_time = item.upload_time.formfield("%Y-%m-%d")#time.strftime("%Y-%m-%d",item.upload_time)   # 鏃堕棿
AttributeError: 'datetime.datetime' object has no attribute 'formfield'
2017-02-16 15:04:11,969 t_global_data.py[line:26] INFO -------Global_data init
2017-02-16 15:04:11,969 t_global_data.py[line:28] INFO -------FILE_PATH F:\pythonCode\lxdzx/files/
2017-02-16 15:04:11,969 t_global_data.py[line:29] INFO -------Global_data init over
2017-02-16 15:04:13,930 exception.py[line:124] ERROR Internal Server Error: /get_all_videos
Traceback (most recent call last):
  File "F:\Python27\lib\site-packages\django\core\handlers\exception.py", line 39, in inner
    response = get_response(request)
  File "F:\Python27\lib\site-packages\django\core\handlers\base.py", line 187, in _get_response
    response = self.process_exception_by_middleware(e, request)
  File "F:\Python27\lib\site-packages\django\core\handlers\base.py", line 185, in _get_response
    response = wrapped_callback(request, *callback_args, **callback_kwargs)
  File "F:\pythonCode\lxdzx\videos_manager\views.py", line 35, in t_get_all_videos
    video.upload_time = item.upload_time.date()+""#time.strftime("%Y-%m-%d",item.upload_time)   # 鏃堕棿
TypeError: unsupported operand type(s) for +: 'datetime.date' and 'str'
2017-02-16 15:04:31,319 t_global_data.py[line:26] INFO -------Global_data init
2017-02-16 15:04:31,319 t_global_data.py[line:28] INFO -------FILE_PATH F:\pythonCode\lxdzx/files/
2017-02-16 15:04:31,322 t_global_data.py[line:29] INFO -------Global_data init over
2017-02-16 15:06:15,165 t_global_data.py[line:26] INFO -------Global_data init
2017-02-16 15:06:15,165 t_global_data.py[line:28] INFO -------FILE_PATH F:\pythonCode\lxdzx/files/
2017-02-16 15:06:15,167 t_global_data.py[line:29] INFO -------Global_data init over
2017-02-16 15:06:59,581 t_global_data.py[line:26] INFO -------Global_data init
2017-02-16 15:06:59,582 t_global_data.py[line:28] INFO -------FILE_PATH F:\pythonCode\lxdzx/files/
2017-02-16 15:06:59,582 t_global_data.py[line:29] INFO -------Global_data init over
2017-02-16 15:07:03,842 exception.py[line:124] ERROR Internal Server Error: /get_all_videos
Traceback (most recent call last):
  File "F:\Python27\lib\site-packages\django\core\handlers\exception.py", line 39, in inner
    response = get_response(request)
  File "F:\Python27\lib\site-packages\django\core\handlers\base.py", line 187, in _get_response
    response = self.process_exception_by_middleware(e, request)
  File "F:\Python27\lib\site-packages\django\core\handlers\base.py", line 185, in _get_response
    response = wrapped_callback(request, *callback_args, **callback_kwargs)
  File "F:\pythonCode\lxdzx\videos_manager\views.py", line 36, in t_get_all_videos
    video.upload_time = time.strftime("%Y-%m-%d", item.upload_time)   # 鏃堕棿
TypeError: argument must be 9-item sequence, not datetime.datetime
2017-02-16 15:08:32,426 t_global_data.py[line:26] INFO -------Global_data init
2017-02-16 15:08:32,426 t_global_data.py[line:28] INFO -------FILE_PATH F:\pythonCode\lxdzx/files/
2017-02-16 15:08:32,426 t_global_data.py[line:29] INFO -------Global_data init over
2017-02-16 15:08:32,792 t_global_data.py[line:26] INFO -------Global_data init
2017-02-16 15:08:32,793 t_global_data.py[line:28] INFO -------FILE_PATH F:\pythonCode\lxdzx/files/
2017-02-16 15:08:32,793 t_global_data.py[line:29] INFO -------Global_data init over
2017-02-16 15:08:35,697 exception.py[line:124] ERROR Internal Server Error: /get_all_videos
Traceback (most recent call last):
  File "F:\Python27\lib\site-packages\django\core\handlers\exception.py", line 39, in inner
    response = get_response(request)
  File "F:\Python27\lib\site-packages\django\core\handlers\base.py", line 187, in _get_response
    response = self.process_exception_by_middleware(e, request)
  File "F:\Python27\lib\site-packages\django\core\handlers\base.py", line 185, in _get_response
    response = wrapped_callback(request, *callback_args, **callback_kwargs)
  File "F:\pythonCode\lxdzx\videos_manager\views.py", line 36, in t_get_all_videos
    video.upload_time = time.strftime("%Y-%m-%d", datetime.datetime.now())   # 鏃堕棿
NameError: global name 'datetime' is not defined
2017-02-16 15:09:18,309 t_global_data.py[line:26] INFO -------Global_data init
2017-02-16 15:09:18,309 t_global_data.py[line:28] INFO -------FILE_PATH F:\pythonCode\lxdzx/files/
2017-02-16 15:09:18,309 t_global_data.py[line:29] INFO -------Global_data init over
2017-02-16 15:09:20,312 exception.py[line:124] ERROR Internal Server Error: /get_all_videos
Traceback (most recent call last):
  File "F:\Python27\lib\site-packages\django\core\handlers\exception.py", line 39, in inner
    response = get_response(request)
  File "F:\Python27\lib\site-packages\django\core\handlers\base.py", line 187, in _get_response
    response = self.process_exception_by_middleware(e, request)
  File "F:\Python27\lib\site-packages\django\core\handlers\base.py", line 185, in _get_response
    response = wrapped_callback(request, *callback_args, **callback_kwargs)
  File "F:\pythonCode\lxdzx\videos_manager\views.py", line 37, in t_get_all_videos
    video.upload_time = time.strftime("%Y-%m-%d", datetime.datetime.now())   # 鏃堕棿
TypeError: argument must be 9-item sequence, not datetime.datetime
2017-02-16 15:09:38,767 t_global_data.py[line:26] INFO -------Global_data init
2017-02-16 15:09:38,767 t_global_data.py[line:28] INFO -------FILE_PATH F:\pythonCode\lxdzx/files/
2017-02-16 15:09:38,767 t_global_data.py[line:29] INFO -------Global_data init over
2017-02-16 15:09:39,296 exception.py[line:124] ERROR Internal Server Error: /get_all_videos
Traceback (most recent call last):
  File "F:\Python27\lib\site-packages\django\core\handlers\exception.py", line 39, in inner
    response = get_response(request)
  File "F:\Python27\lib\site-packages\django\core\handlers\base.py", line 187, in _get_response
    response = self.process_exception_by_middleware(e, request)
  File "F:\Python27\lib\site-packages\django\core\handlers\base.py", line 185, in _get_response
    response = wrapped_callback(request, *callback_args, **callback_kwargs)
  File "F:\pythonCode\lxdzx\videos_manager\views.py", line 37, in t_get_all_videos
    video.upload_time = time.strptime("%Y-%m-%d", datetime.datetime.now())   # 鏃堕棿
  File "F:\Python27\lib\_strptime.py", line 478, in _strptime_time
    return _strptime(data_string, format)[0]
  File "F:\Python27\lib\_strptime.py", line 315, in _strptime
    format_regex = _TimeRE_cache.compile(format)
  File "F:\Python27\lib\_strptime.py", line 269, in compile
    return re_compile(self.pattern(format), IGNORECASE)
  File "F:\Python27\lib\_strptime.py", line 256, in pattern
    format = regex_chars.sub(r"\\\1", format)
TypeError: expected string or buffer
2017-02-16 15:10:07,614 t_global_data.py[line:26] INFO -------Global_data init
2017-02-16 15:10:07,615 t_global_data.py[line:28] INFO -------FILE_PATH F:\pythonCode\lxdzx/files/
2017-02-16 15:10:07,615 t_global_data.py[line:29] INFO -------Global_data init over
2017-02-16 15:10:11,371 t_global_data.py[line:26] INFO -------Global_data init
2017-02-16 15:10:11,371 t_global_data.py[line:28] INFO -------FILE_PATH F:\pythonCode\lxdzx/files/
2017-02-16 15:10:11,371 t_global_data.py[line:29] INFO -------Global_data init over
2017-02-16 15:10:12,279 exception.py[line:124] ERROR Internal Server Error: /get_all_videos
Traceback (most recent call last):
  File "F:\Python27\lib\site-packages\django\core\handlers\exception.py", line 39, in inner
    response = get_response(request)
  File "F:\Python27\lib\site-packages\django\core\handlers\base.py", line 187, in _get_response
    response = self.process_exception_by_middleware(e, request)
  File "F:\Python27\lib\site-packages\django\core\handlers\base.py", line 185, in _get_response
    response = wrapped_callback(request, *callback_args, **callback_kwargs)
  File "F:\pythonCode\lxdzx\videos_manager\views.py", line 37, in t_get_all_videos
    video.upload_time = datetime.datetime.now().strptime("%Y-%m-%d")   # 鏃堕棿
TypeError: strptime() takes exactly 2 arguments (1 given)
2017-02-16 15:10:26,683 t_global_data.py[line:26] INFO -------Global_data init
2017-02-16 15:10:26,683 t_global_data.py[line:28] INFO -------FILE_PATH F:\pythonCode\lxdzx/files/
2017-02-16 15:10:26,684 t_global_data.py[line:29] INFO -------Global_data init over
2017-02-16 15:10:46,091 t_global_data.py[line:26] INFO -------Global_data init
2017-02-16 15:10:46,092 t_global_data.py[line:28] INFO -------FILE_PATH F:\pythonCode\lxdzx/files/
2017-02-16 15:10:46,092 t_global_data.py[line:29] INFO -------Global_data init over
2017-02-16 15:12:13,279 t_global_data.py[line:26] INFO -------Global_data init
2017-02-16 15:12:13,279 t_global_data.py[line:28] INFO -------FILE_PATH F:\pythonCode\lxdzx/files/
2017-02-16 15:12:13,279 t_global_data.py[line:29] INFO -------Global_data init over
2017-02-16 15:12:19,158 exception.py[line:124] ERROR Internal Server Error: /get_all_videos
Traceback (most recent call last):
  File "F:\Python27\lib\site-packages\django\core\handlers\exception.py", line 39, in inner
    response = get_response(request)
  File "F:\Python27\lib\site-packages\django\core\handlers\base.py", line 187, in _get_response
    response = self.process_exception_by_middleware(e, request)
  File "F:\Python27\lib\site-packages\django\core\handlers\base.py", line 185, in _get_response
    response = wrapped_callback(request, *callback_args, **callback_kwargs)
  File "F:\pythonCode\lxdzx\videos_manager\views.py", line 37, in t_get_all_videos
    video.upload_time = item.upload_time.strftime("%Y-%m-%d %H:%M:%s")   # 鏃堕棿
ValueError: Invalid format string
2017-02-16 15:12:25,332 t_global_data.py[line:26] INFO -------Global_data init
2017-02-16 15:12:25,332 t_global_data.py[line:28] INFO -------FILE_PATH F:\pythonCode\lxdzx/files/
2017-02-16 15:12:25,332 t_global_data.py[line:29] INFO -------Global_data init over
2017-02-16 15:12:28,007 t_global_data.py[line:26] INFO -------Global_data init
2017-02-16 15:12:28,007 t_global_data.py[line:28] INFO -------FILE_PATH F:\pythonCode\lxdzx/files/
2017-02-16 15:12:28,007 t_global_data.py[line:29] INFO -------Global_data init over
2017-02-16 15:12:35,970 t_global_data.py[line:26] INFO -------Global_data init
2017-02-16 15:12:35,970 t_global_data.py[line:28] INFO -------FILE_PATH F:\pythonCode\lxdzx/files/
2017-02-16 15:12:35,970 t_global_data.py[line:29] INFO -------Global_data init over
2017-02-16 15:13:18,348 t_global_data.py[line:26] INFO -------Global_data init
2017-02-16 15:13:18,348 t_global_data.py[line:28] INFO -------FILE_PATH F:\pythonCode\lxdzx/files/
2017-02-16 15:13:18,348 t_global_data.py[line:29] INFO -------Global_data init over
2017-02-16 15:13:31,563 t_global_data.py[line:26] INFO -------Global_data init
2017-02-16 15:13:31,565 t_global_data.py[line:28] INFO -------FILE_PATH F:\pythonCode\lxdzx/files/
2017-02-16 15:13:31,565 t_global_data.py[line:29] INFO -------Global_data init over
2017-02-16 15:13:36,323 t_global_data.py[line:26] INFO -------Global_data init
2017-02-16 15:13:36,323 t_global_data.py[line:28] INFO -------FILE_PATH F:\pythonCode\lxdzx/files/
2017-02-16 15:13:36,323 t_global_data.py[line:29] INFO -------Global_data init over
2017-02-16 15:13:44,313 t_global_data.py[line:26] INFO -------Global_data init
2017-02-16 15:13:44,315 t_global_data.py[line:28] INFO -------FILE_PATH F:\pythonCode\lxdzx/files/
2017-02-16 15:13:44,315 t_global_data.py[line:29] INFO -------Global_data init over
2017-02-16 15:13:53,250 t_global_data.py[line:26] INFO -------Global_data init
2017-02-16 15:13:53,252 t_global_data.py[line:28] INFO -------FILE_PATH F:\pythonCode\lxdzx/files/
2017-02-16 15:13:53,252 t_global_data.py[line:29] INFO -------Global_data init over
2017-02-16 15:13:55,950 t_global_data.py[line:26] INFO -------Global_data init
2017-02-16 15:13:55,950 t_global_data.py[line:28] INFO -------FILE_PATH F:\pythonCode\lxdzx/files/
2017-02-16 15:13:55,950 t_global_data.py[line:29] INFO -------Global_data init over
2017-02-16 15:14:09,098 t_global_data.py[line:26] INFO -------Global_data init
2017-02-16 15:14:09,099 t_global_data.py[line:28] INFO -------FILE_PATH F:\pythonCode\lxdzx/files/
2017-02-16 15:14:09,099 t_global_data.py[line:29] INFO -------Global_data init over
2017-02-16 15:15:30,085 t_global_data.py[line:26] INFO -------Global_data init
2017-02-16 15:15:30,085 t_global_data.py[line:28] INFO -------FILE_PATH F:\pythonCode\lxdzx/files/
2017-02-16 15:15:30,085 t_global_data.py[line:29] INFO -------Global_data init over
2017-02-16 15:15:36,967 t_global_data.py[line:26] INFO -------Global_data init
2017-02-16 15:15:36,967 t_global_data.py[line:28] INFO -------FILE_PATH F:\pythonCode\lxdzx/files/
2017-02-16 15:15:36,967 t_global_data.py[line:29] INFO -------Global_data init over
2017-02-16 15:15:52,193 t_global_data.py[line:26] INFO -------Global_data init
2017-02-16 15:15:52,193 t_global_data.py[line:28] INFO -------FILE_PATH F:\pythonCode\lxdzx/files/
2017-02-16 15:15:52,194 t_global_data.py[line:29] INFO -------Global_data init over
2017-02-16 15:16:04,270 t_global_data.py[line:26] INFO -------Global_data init
2017-02-16 15:16:04,272 t_global_data.py[line:28] INFO -------FILE_PATH F:\pythonCode\lxdzx/files/
2017-02-16 15:16:04,272 t_global_data.py[line:29] INFO -------Global_data init over
2017-02-16 15:16:07,940 t_global_data.py[line:26] INFO -------Global_data init
2017-02-16 15:16:07,941 t_global_data.py[line:28] INFO -------FILE_PATH F:\pythonCode\lxdzx/files/
2017-02-16 15:16:07,943 t_global_data.py[line:29] INFO -------Global_data init over
2017-02-16 15:16:10,578 t_global_data.py[line:26] INFO -------Global_data init
2017-02-16 15:16:10,579 t_global_data.py[line:28] INFO -------FILE_PATH F:\pythonCode\lxdzx/files/
2017-02-16 15:16:10,579 t_global_data.py[line:29] INFO -------Global_data init over
2017-02-16 15:16:16,335 t_global_data.py[line:26] INFO -------Global_data init
2017-02-16 15:16:16,335 t_global_data.py[line:28] INFO -------FILE_PATH F:\pythonCode\lxdzx/files/
2017-02-16 15:16:16,335 t_global_data.py[line:29] INFO -------Global_data init over
2017-02-16 15:16:33,631 t_global_data.py[line:26] INFO -------Global_data init
2017-02-16 15:16:33,632 t_global_data.py[line:28] INFO -------FILE_PATH F:\pythonCode\lxdzx/files/
2017-02-16 15:16:33,632 t_global_data.py[line:29] INFO -------Global_data init over
2017-02-16 15:16:40,471 t_global_data.py[line:26] INFO -------Global_data init
2017-02-16 15:16:40,473 t_global_data.py[line:28] INFO -------FILE_PATH F:\pythonCode\lxdzx/files/
2017-02-16 15:16:40,473 t_global_data.py[line:29] INFO -------Global_data init over
2017-02-16 15:17:21,723 t_global_data.py[line:26] INFO -------Global_data init
2017-02-16 15:17:21,723 t_global_data.py[line:28] INFO -------FILE_PATH F:\pythonCode\lxdzx/files/
2017-02-16 15:17:21,724 t_global_data.py[line:29] INFO -------Global_data init over
2017-02-16 15:17:29,611 t_global_data.py[line:26] INFO -------Global_data init
2017-02-16 15:17:29,611 t_global_data.py[line:28] INFO -------FILE_PATH F:\pythonCode\lxdzx/files/
2017-02-16 15:17:29,611 t_global_data.py[line:29] INFO -------Global_data init over
2017-02-16 15:17:43,865 t_global_data.py[line:26] INFO -------Global_data init
2017-02-16 15:17:43,865 t_global_data.py[line:28] INFO -------FILE_PATH F:\pythonCode\lxdzx/files/
2017-02-16 15:17:43,865 t_global_data.py[line:29] INFO -------Global_data init over
2017-02-16 15:17:45,970 exception.py[line:124] ERROR Internal Server Error: /get_all_videos
Traceback (most recent call last):
  File "F:\Python27\lib\site-packages\django\core\handlers\exception.py", line 39, in inner
    response = get_response(request)
  File "F:\Python27\lib\site-packages\django\core\handlers\base.py", line 187, in _get_response
    response = self.process_exception_by_middleware(e, request)
  File "F:\Python27\lib\site-packages\django\core\handlers\base.py", line 185, in _get_response
    response = wrapped_callback(request, *callback_args, **callback_kwargs)
  File "F:\pythonCode\lxdzx\videos_manager\views.py", line 41, in t_get_all_videos
    res = HttpResponse(TJsonTools.tJsonEncode(tj_videos).replaceall("},", os.linesep))
AttributeError: 'unicode' object has no attribute 'replaceall'
2017-02-16 15:19:18,450 t_global_data.py[line:26] INFO -------Global_data init
2017-02-16 15:19:18,450 t_global_data.py[line:28] INFO -------FILE_PATH F:\pythonCode\lxdzx/files/
2017-02-16 15:19:18,450 t_global_data.py[line:29] INFO -------Global_data init over
2017-02-16 15:19:20,388 exception.py[line:124] ERROR Internal Server Error: /get_all_videos
Traceback (most recent call last):
  File "F:\Python27\lib\site-packages\django\core\handlers\exception.py", line 39, in inner
    response = get_response(request)
  File "F:\Python27\lib\site-packages\django\core\handlers\base.py", line 187, in _get_response
    response = self.process_exception_by_middleware(e, request)
  File "F:\Python27\lib\site-packages\django\core\handlers\base.py", line 185, in _get_response
    response = wrapped_callback(request, *callback_args, **callback_kwargs)
  File "F:\pythonCode\lxdzx\videos_manager\views.py", line 41, in t_get_all_videos
    res = HttpResponse(TJsonTools.tJsonEncode(tj_videos).replaceall("},", "},\\"))
AttributeError: 'unicode' object has no attribute 'replaceall'
2017-02-16 15:19:21,223 exception.py[line:124] ERROR Internal Server Error: /get_all_videos
Traceback (most recent call last):
  File "F:\Python27\lib\site-packages\django\core\handlers\exception.py", line 39, in inner
    response = get_response(request)
  File "F:\Python27\lib\site-packages\django\core\handlers\base.py", line 187, in _get_response
    response = self.process_exception_by_middleware(e, request)
  File "F:\Python27\lib\site-packages\django\core\handlers\base.py", line 185, in _get_response
    response = wrapped_callback(request, *callback_args, **callback_kwargs)
  File "F:\pythonCode\lxdzx\videos_manager\views.py", line 41, in t_get_all_videos
    res = HttpResponse(TJsonTools.tJsonEncode(tj_videos).replaceall("},", "},\\"))
AttributeError: 'unicode' object has no attribute 'replaceall'
2017-02-16 15:19:29,526 t_global_data.py[line:26] INFO -------Global_data init
2017-02-16 15:19:29,526 t_global_data.py[line:28] INFO -------FILE_PATH F:\pythonCode\lxdzx/files/
2017-02-16 15:19:29,526 t_global_data.py[line:29] INFO -------Global_data init over
2017-02-16 15:19:32,170 t_global_data.py[line:26] INFO -------Global_data init
2017-02-16 15:19:32,170 t_global_data.py[line:28] INFO -------FILE_PATH F:\pythonCode\lxdzx/files/
2017-02-16 15:19:32,170 t_global_data.py[line:29] INFO -------Global_data init over
2017-02-16 15:19:33,950 exception.py[line:124] ERROR Internal Server Error: /get_all_videos
Traceback (most recent call last):
  File "F:\Python27\lib\site-packages\django\core\handlers\exception.py", line 39, in inner
    response = get_response(request)
  File "F:\Python27\lib\site-packages\django\core\handlers\base.py", line 187, in _get_response
    response = self.process_exception_by_middleware(e, request)
  File "F:\Python27\lib\site-packages\django\core\handlers\base.py", line 185, in _get_response
    response = wrapped_callback(request, *callback_args, **callback_kwargs)
  File "F:\pythonCode\lxdzx\videos_manager\views.py", line 41, in t_get_all_videos
    res = HttpResponse(TJsonTools.tJsonEncode(tj_videos).replaceall("},", "},\\"))
AttributeError: 'unicode' object has no attribute 'replaceall'
2017-02-16 15:19:42,171 t_global_data.py[line:26] INFO -------Global_data init
2017-02-16 15:19:42,171 t_global_data.py[line:28] INFO -------FILE_PATH F:\pythonCode\lxdzx/files/
2017-02-16 15:19:42,173 t_global_data.py[line:29] INFO -------Global_data init over
2017-02-16 15:20:10,971 t_global_data.py[line:26] INFO -------Global_data init
2017-02-16 15:20:10,971 t_global_data.py[line:28] INFO -------FILE_PATH F:\pythonCode\lxdzx/files/
2017-02-16 15:20:10,973 t_global_data.py[line:29] INFO -------Global_data init over
2017-02-16 15:20:22,046 t_global_data.py[line:26] INFO -------Global_data init
2017-02-16 15:20:22,046 t_global_data.py[line:28] INFO -------FILE_PATH F:\pythonCode\lxdzx/files/
2017-02-16 15:20:22,046 t_global_data.py[line:29] INFO -------Global_data init over
2017-02-16 15:20:40,387 t_global_data.py[line:26] INFO -------Global_data init
2017-02-16 15:20:40,387 t_global_data.py[line:28] INFO -------FILE_PATH F:\pythonCode\lxdzx/files/
2017-02-16 15:20:40,387 t_global_data.py[line:29] INFO -------Global_data init over
2017-02-16 15:21:07,092 t_global_data.py[line:26] INFO -------Global_data init
2017-02-16 15:21:07,092 t_global_data.py[line:28] INFO -------FILE_PATH F:\pythonCode\lxdzx/files/
2017-02-16 15:21:07,092 t_global_data.py[line:29] INFO -------Global_data init over
2017-02-16 15:21:27,572 t_global_data.py[line:26] INFO -------Global_data init
2017-02-16 15:21:27,572 t_global_data.py[line:28] INFO -------FILE_PATH F:\pythonCode\lxdzx/files/
2017-02-16 15:21:27,572 t_global_data.py[line:29] INFO -------Global_data init over
